Workbook
Name benhVien: BenhVien!$A$3:$D$14894
Name danToc: 'Dân tộc'!$A$3:$B$58
Name huyen: Xa!$A$3:$D$3500
Name loai_khai_bao: 'Tổng hợp '!$B$25:$B$29
Name ma_huyen: Xa!$C$3:$C$3500
Name ma_huyen_xa: #REF!
Name ma_loai_phuong_an: 'Tổng hợp '!$D$43:$D$88
Name ma_mqh: 'Tổng hợp '!$J$15:$K$37
Name ma_phuong_an: 'Tổng hợp '!$C$43:$C$88
Name ma_tinh: Tinh!$B$3:$B$67
Name ma_tinh_benh_vien: TinhBenhVien!$B$3:$B$65
Name ma_tinh_bv: BenhVien!$D$3:$D$14894
Name ma_tinh_huyen: Xa!$D$3:$D$3500
Name ma_xa: #REF!
Name MaLoaiGiayTo: 'Tổng hợp '!$I$4:$I$8
Name mqh: 'Tổng hợp '!$J$15:$J$37
Name phuong_an: 'Tổng hợp '!$B$43:$D$88
Name quanhe: 'Tổng hợp '!$M$4:$N$26
Name quocTich: QuocTich!$A$3:$B$243
Name ten_danToc: 'Dân tộc'!$A$3:$A$58
Name ten_huyen: Xa!$B$3:$B$3500
Name ten_phuong_an: 'Tổng hợp '!$B$43:$B$88
Name ten_quoctich: QuocTich!$A$3:$A$243
Name ten_tinh: Tinh!$A$3:$A$67
Name ten_tinh_Benh_vien: TinhBenhVien!$A$3:$A$65
Name ten_xa: #REF!
Name tinh: Tinh!$A$3:$B$67
Name TinhBenhVien: TinhBenhVien!$A$3:$B$65
Name xa: #REF!

Sheet Dữ Liệu
A1: CHÚ Ý: Những cột màu xanh đậm là bắt buộc phải nhập; Dữ liệu nhập bắt đầu từ dòng thứ 4. | C1: tra cứu tại https://baohiemxahoi.gov.vn/tracuu/Pages/tra-cuu-ho-gia-dinh.aspx | K1: chỉ dành cho những lao động đóng theo hệ số lương. Lao động đóng theo tiền lương KHÔNG NHẬP cột này | N1: Chỉ được nhập số tiền, KHÔNG CHO PHÉP nhập hệ số | R1: Nhập khi Giảm hẳn do chết | S1: tăng mới điền số HĐLĐ, mã bệnh viện KCB ban đầu - mã phương án sẽ được tự động điền vào Ghi chú khi import file vào phần mềm. | T1: Dùng dấu phẩy để phân tách hàng thập phân | U1: 0: không 1:có | V1: 0: không 1:có | Y1: K1: nơi người dân tộc thiểu số, người nghèo sống tại địa bàn khó khăn K2: nơi người dân tộc thiểu số, người nghèo sống tại địa bàn đặc biệt khó khăn K3: Nơi người tham gia BHYT sống tại xã đảo, huyện đảo Nếu không thuộc 3 khu vực trên thì để trống. | Z1: Tra cứu tại: https://docs.google.com/spreadsheets/d/1fmVEVFMvAZ6-KVTAwfg89OH5ejjPNvdcgNos1aHRGC4/edit?usp=sharing | AA1: Điền x nếu muốn phần mềm lưu lại những thông tin của tờ khai TK1. Nếu không điền x, những thông tin tờ Tk1 sẽ không được lưu lại. | AD1: ngày/tháng/năm tháng/năm hoặc năm sinh | AE1: Nam:1 Nữ: 0 | AH1: tra cứu những dân tộc khác tên nhưng cùng mã với nhau tại sheet Dân tộc | AJ1: Nơi đăng ký khám chữa bệnh ban đầu | AN1: Địa chỉ Khai Sinh (Nhập hoặc chọn tên tỉnh/huyện/xã, cột mã là tự sinh) | AT1: Địa chỉ liên hệ (Nhập hoặc chọn tên tỉnh/xã, cột mã là tự sinh) | BC1: Dành cho đối tượng tự nguyện | BE1: ghi yêu cầu cấp số/thẻ hoặc cả 2. trường hợp cấp lại sổ do mất/hỏng ghi quá trình đóng | BI1: Giữ vị trí việc làm là nhà quản lý | BK1: Giữ vị trí việc Chuyên môn kỹ thuật bậc cao | BM1: Giữ vị trí việc Chuyên môn kỹ thuật bậc trung | BO1: Giữ vị trí việc làm khác | BQ1: Ngành nghề nặng nhọc độc hại | BT1: Hợp đồng lao động xác định thời hạn | BV1: Hợp đồng lao động khác (dưới 1 tháng, thử việc) | BX1: Không nhận:0 Nhận:1 | BY1: Không nhận:0 Nhận:1 | BZ1: Số nhà, thôn/xóm,.. | CA1: Địa chỉ nhận bản giấy (Nhập hoặc chọn tên tỉnh/xã, cột mã là tự sinh)
A2: ID Lao động | B2: Họ tên | C2: Mã số BHXH | D2: Loại khai báo | E2: Mã loại khai báo | F2: Phương án | G2: Mã Phương án | H2: Chức vụ | I2: Nơi làm việc | J2: Tiền lương/ Hệ số lương | K2: Phụ cấp CV | L2: Phụ cấp TNVK (%) | M2: Phụ cấp TN Nghề (%) | N2: Phụ cấp lương | O2: Phụ cấp bổ sung | P2: Từ tháng | Q2: Đến tháng | R2: Ngày chết | S2: Ghi chú | T2: Tỷ lệ đóng(%) | U2: Tính lãi | V2: Đã có sổ | W2: Mức hưởng BHYT | X2: Phòng ban làm việc | Y2: Mã vùng sinh sống | Z2: Mã vùng lương tối thiểu | AA2: Bổ sung thêm TK1 | AB2: CMND | AC2: Mã hộ gia đình | AD2: Ngày sinh | AE2: Giới tính | AF2: Quốc tịch | AG2: Mã quốc tịch | AH2: Dân tộc | AI2: Mã Dân tộc | AJ2: Tỉnh - Bệnh viện | AK2: Mã Tỉnh - Bệnh viện | AL2: Bệnh viện (KCB ban đầu) | AM2: Mã Bệnh viện | AN2: Tỉnh - Khai sinh | AO2: Mã Tỉnh - Khai sinh | AP2: Xã - Khai sinh | AQ2: Mã xã - Khai sinh | AR2: Xã - Khai sinh | AS2: Mã xã - Khai sinh | AT2: Tỉnh - Địa chỉ liên hệ | AU2: Mã tỉnh - Địa chỉ liên hệ | AV2: Xã - Địa chỉ liên hệ | AW2: Mã xã - Địa chỉ liên hệ | AX2: Xã - Địa chỉ liên hệ | AY2: Mã xã - Địa chỉ liên hệ | AZ2: Địa chỉ nhận hồ sơ | BA2: Tên cha/mẹ/người giám hộ | BB2: Điện thoại liên hệ | BC2: Mức tiền đóng | BD2: Phương thức đóng | BE2: Nội dung yêu cầu thay đổi | BF2: Hồ sơ kèm theo | BG2: Email liên hệ | BH2: Địa chỉ khai sinh | BI2: Ngày bắt đầu | BJ2: Ngày kết thúc | BK2: Ngày bắt đầu | BL2: Ngày kết thúc | BM2: Ngày bắt đầu | BN2: Ngày kết thúc | BO2: Ngày bắt đầu | BP2: Ngày kết thúc | BQ2: Ngày bắt đầu | BR2: Ngày kết thúc | BS2: Ngày bắt đầu hợp đồng lao động không xác định thời hạn | BT2: Ngày bắt đầu | BU2: Ngày kết thúc | BV2: Ngày bắt đầu | BW2: Ngày kết thúc | BX2: Nhận bản điện tử | BY2: Nhận bản giấy | BZ2: Địa chỉ nhận bản giấy | CA2: Tỉnh - Địa chỉ nhận bản giấy | CB2: Mã tỉnh - Địa chỉ nhận bản giấy | CC2: Xã - Địa chỉ nhận bản giấy | CD2: Xã - Địa chỉ nhận bản giấy
A3: STT | B3: HoTen | C3: MasoBHXH | D3: TenLoaiKhaiBao | E3: Loai | F3: TenPhuongAn | G3: PA | H3: ChucVu | I3: NoiLamViec | J3: TienLuong | K3: PhuCapCV | L3: PhuCapTNVK | M3: PhuCapTNNghe | N3: PhuCapLuong | O3: PhuCapBosung | P3: TuThang | Q3: DenThang | R3: NgayChet | S3: Ghichu | T3: TyleDong | U3: TinhLai | V3: DaCoSo | W3: MucHuong | X3: MaPhongBan | Y3: MavungSS | Z3: MavungLTT | AA3: Tk1_Save | AB3: CMND | AC3: Maho_Giadinh | AD3: NgaySinh | AE3: GioiTinh | AF3: TenQuocTich | AG3: QuocTich | AH3: TenDanToc | AI3: DanToc | AJ3: TenTinhBenhVien | AK3: MaTinhBenhVien | AL3: TenBenhVien | AM3: MaBenhVien | AN3: TenTinhKS | AO3: Matinh_KS | AP3: TenXaKS | AQ3: Maxa_KS | AT3: TenTinhNN | AU3: Matinh_NN | AV3: TenXaNN | AW3: Maxa_NN | AX3: TenXaNN | AY3: Maxa_NN | AZ3: Diachi_NN | BA3: Ten_ChaMe_Giamho | BB3: Dienthoai_LH | BC3: Mucdong | BD3: Phuongthuc | BE3: Noidung_Thaydoi | BF3: HosoKemtheo | BG3: Email_LH | BH3: Diachi_KS | BI3: Vtvl_nql_tungay | BJ3: Vtvl_nql_denngay | BK3: Vtvl_cmktbc_tungay | BL3: Vtvl_cmktbc_denngay | BM3: Vtvl_cmktbt_tungay | BN3: Vtvl_cmktbt_denngay | BO3: Vtvl_khac_tungay | BP3: Vtvl_khac_denngay | BQ3: Nndh_tungay | BR3: Nndh_denngay | BS3: Hdld_tungay | BT3: Hdld_xdth_tungay | BU3: Hdld_xdth_denngay | BV3: Hdld_khac_tungay | BW3: Hdld_khac_denngay | BX3: Nhan_BanDientu | BY3: Nhan_Bangiay | BZ3: Diachi_NhanBangiay | CA3: Tinh_NhanBangiay | CB3: Matinh_NhanBangiay | CC3: Xa_NhanBangiay | CD3: Maxa_NhanBangiay
A4: 1 | B4: Bùi Văn A | C4: 1234567890 | D4: Tăng lao động | E4: =IF(ISNA(VLOOKUP(D4,'Tổng hợp '!$B$25:$C$29,2,FALSE)),"",VLOOKUP(D4,'Tổng hợp '!$B$25:$C$29,2,FALSE)) -> 1 | F4: ON - Đi làm lại | G4: =IF(ISNA(VLOOKUP(F4,phuong_an,2,FALSE)),"",VLOOKUP(F4,phuong_an,2,FALSE)) -> ON | H4: nhân viên | I4: Cầu Giấy - Hà Nội | J4: 5000000 | P4: 02/2019 | Q4: 02/2020 | S4: Tăng mới | T4: 32,5 | U4: 1 | V4: 0 | Y4: K1 | AA4: x | AB4: 9817654321 | AC4: 123 | AD4: 1990 | AE4: 1 | AF4: Việt Nam | AG4: =IF(ISNA(VLOOKUP(AF4,quocTich,2,FALSE)),"",VLOOKUP(AF4,quocTich,2,FALSE)) -> VN | AH4: Kinh | AI4: =IF(ISNA(VLOOKUP(AH4,danToc,2,FALSE)),"",VLOOKUP(AH4,danToc,2,FALSE)) -> 01 | AJ4: Tỉnh Lai Châu | AK4: =IF(ISNA(VLOOKUP(AJ4,TinhBenhVien!A:B,2,FALSE)),"",VLOOKUP(AJ4,TinhBenhVien!A:B,2,FALSE)) -> 12 | AL4: Trạm y tế xã Tả Lèng | AM4: =IF(ISNA(VLOOKUP(AL4&AK4,benhVien,3,FALSE)),"",VLOOKUP(AL4&AK4,benhVien,3,FALSE)) -> 12005 | AN4: Tỉnh Lào Cai | AO4: =IF(ISNA(VLOOKUP(AN4,tinh,2,FALSE)),"",VLOOKUP(AN4,tinh,2,FALSE)) -> 15 | AP4: Xã Phình Hồ | AQ4: =IF(ISNA(VLOOKUP(AP4&AO4,huyen,3,FALSE)),"",VLOOKUP(AP4&AO4,huyen,3,FALSE)) -> 04609 | AR4: Phường Quảng An | AS4: =IF(ISNA(VLOOKUP(AR4&AQ4,xa,3,FALSE)),"",VLOOKUP(AR4&AQ4,xa,3,FALSE)) -> #REF! | AT4: Thành phố Hồ Chí Minh | AU4: =IF(ISNA(VLOOKUP(AT4,tinh,2,FALSE)),"",VLOOKUP(AT4,tinh,2,FALSE)) -> 79 | AV4: Phường An Khê | AW4: =IF(ISNA(VLOOKUP(AV4&AU4,huyen,3,FALSE)),"",VLOOKUP(AV4&AU4,huyen,3,FALSE)) | AX4: Xã Nam Quang | AY4: =IF(ISNA(VLOOKUP(AX4&AW4,xa,3,FALSE)),"",VLOOKUP(AX4&AW4,xa,3,FALSE)) -> #REF! | BI4: 02/02/2020 | BJ4: 03/02/2020 | BK4: 04/02/2020 | BL4: 05/02/2020 | BM4: 06/02/2020 | BN4: 07/02/2020 | BO4: 08/02/2020 | BP4: 09/02/2020 | BQ4: 10/02/2020 | BR4: 11/02/2020 | BS4: 12/02/2020 | BT4: 13/02/2020 | BU4: 14/02/2020 | BV4: 15/02/2020 | BW4: 16/02/2020 | BX4: 0 | BY4: 1 | CA4: Tỉnh Hà Giang | CB4: =IF(ISNA(VLOOKUP(CA4,tinh,2,FALSE)),"",VLOOKUP(CA4,tinh,2,FALSE)) | CC4: Huyện Mèo Vạc | CD4: =IF(ISNA(VLOOKUP(CC4&CB4,huyen,3,FALSE)),"",VLOOKUP(CC4&CB4,huyen,3,FALSE))
E5: =IF(ISNA(VLOOKUP(D5,'Tổng hợp '!$B$25:$C$29,2,FALSE)),"",VLOOKUP(D5,'Tổng hợp '!$B$25:$C$29,2,FALSE)) | G5: =IF(ISNA(VLOOKUP(F5,phuong_an,2,FALSE)),"",VLOOKUP(F5,phuong_an,2,FALSE)) | AG5: =IF(ISNA(VLOOKUP(AF5,quocTich,2,FALSE)),"",VLOOKUP(AF5,quocTich,2,FALSE)) | AI5: =IF(ISNA(VLOOKUP(AH5,danToc,2,FALSE)),"",VLOOKUP(AH5,danToc,2,FALSE)) | AJ5: Tỉnh Đồng Nai | AK5: =IF(ISNA(VLOOKUP(AJ5,TinhBenhVien!A:B,2,FALSE)),"",VLOOKUP(AJ5,TinhBenhVien!A:B,2,FALSE)) -> 75 | AL5: Trung tâm Y tế khu vực Bù Đốp | AM5: =IF(ISNA(VLOOKUP(AL5&AK5,benhVien,3,FALSE)),"",VLOOKUP(AL5&AK5,benhVien,3,FALSE)) -> 70007 | AN5: Tỉnh Quảng Ngãi | AO5: =IF(ISNA(VLOOKUP(AN5,tinh,2,FALSE)),"",VLOOKUP(AN5,tinh,2,FALSE)) -> 51 | AP5: Huyện Lý Sơn | AQ5: =IF(ISNA(VLOOKUP(AP5&AO5,huyen,3,FALSE)),"",VLOOKUP(AP5&AO5,huyen,3,FALSE)) | AR5: Xã Đảo Lý Sơn | AS5: =IF(ISNA(VLOOKUP(AR5&AQ5,xa,3,FALSE)),"",VLOOKUP(AR5&AQ5,xa,3,FALSE)) -> #REF! | AU5: =IF(ISNA(VLOOKUP(AT5,tinh,2,FALSE)),"",VLOOKUP(AT5,tinh,2,FALSE)) | AW5: =IF(ISNA(VLOOKUP(AV5&AU5,huyen,3,FALSE)),"",VLOOKUP(AV5&AU5,huyen,3,FALSE)) | AY5: =IF(ISNA(VLOOKUP(AX5&AW5,xa,3,FALSE)),"",VLOOKUP(AX5&AW5,xa,3,FALSE)) -> #REF! | BX5: 1 | BY5: 0 | CB5: =IF(ISNA(VLOOKUP(CA5,tinh,2,FALSE)),"",VLOOKUP(CA5,tinh,2,FALSE)) | CD5: =IF(ISNA(VLOOKUP(CC5&CB5,huyen,3,FALSE)),"",VLOOKUP(CC5&CB5,huyen,3,FALSE))
E6: =IF(ISNA(VLOOKUP(D6,'Tổng hợp '!$B$25:$C$29,2,FALSE)),"",VLOOKUP(D6,'Tổng hợp '!$B$25:$C$29,2,FALSE)) | G6: =IF(ISNA(VLOOKUP(F6,phuong_an,2,FALSE)),"",VLOOKUP(F6,phuong_an,2,FALSE)) | AG6: =IF(ISNA(VLOOKUP(AF6,quocTich,2,FALSE)),"",VLOOKUP(AF6,quocTich,2,FALSE)) | AI6: =IF(ISNA(VLOOKUP(AH6,danToc,2,FALSE)),"",VLOOKUP(AH6,danToc,2,FALSE)) | AJ6: Tỉnh Lâm Đồng | AK6: =IF(ISNA(VLOOKUP(AJ6,TinhBenhVien!A:B,2,FALSE)),"",VLOOKUP(AJ6,TinhBenhVien!A:B,2,FALSE)) -> 68 | AL6: Trung tâm Y tế khu vực Tuy Phong | AM6: =IF(ISNA(VLOOKUP(AL6&AK6,benhVien,3,FALSE)),"",VLOOKUP(AL6&AK6,benhVien,3,FALSE)) -> 60004 | AO6: =IF(ISNA(VLOOKUP(AN6,tinh,2,FALSE)),"",VLOOKUP(AN6,tinh,2,FALSE)) | AQ6: =IF(ISNA(VLOOKUP(AP6&AO6,huyen,3,FALSE)),"",VLOOKUP(AP6&AO6,huyen,3,FALSE)) | AS6: =IF(ISNA(VLOOKUP(AR5&AQ6,xa,3,FALSE)),"",VLOOKUP(AR5&AQ6,xa,3,FALSE)) -> #REF! | AU6: =IF(ISNA(VLOOKUP(AT6,tinh,2,FALSE)),"",VLOOKUP(AT6,tinh,2,FALSE)) | AW6: =IF(ISNA(VLOOKUP(AV6&AU6,huyen,3,FALSE)),"",VLOOKUP(AV6&AU6,huyen,3,FALSE)) | AY6: =IF(ISNA(VLOOKUP(AX6&AW6,xa,3,FALSE)),"",VLOOKUP(AX6&AW6,xa,3,FALSE)) -> #REF! | CB6: =IF(ISNA(VLOOKUP(CA6,tinh,2,FALSE)),"",VLOOKUP(CA6,tinh,2,FALSE)) | CD6: =IF(ISNA(VLOOKUP(CC6&CB6,huyen,3,FALSE)),"",VLOOKUP(CC6&CB6,huyen,3,FALSE))
E7: =IF(ISNA(VLOOKUP(D7,'Tổng hợp '!$B$25:$C$29,2,FALSE)),"",VLOOKUP(D7,'Tổng hợp '!$B$25:$C$29,2,FALSE)) | G7: =IF(ISNA(VLOOKUP(F7,phuong_an,2,FALSE)),"",VLOOKUP(F7,phuong_an,2,FALSE)) | AG7: =IF(ISNA(VLOOKUP(AF7,quocTich,2,FALSE)),"",VLOOKUP(AF7,quocTich,2,FALSE)) | AI7: =IF(ISNA(VLOOKUP(AH7,danToc,2,FALSE)),"",VLOOKUP(AH7,danToc,2,FALSE)) | AK7: =IF(ISNA(VLOOKUP(AJ7,TinhBenhVien!A:B,2,FALSE)),"",VLOOKUP(AJ7,TinhBenhVien!A:B,2,FALSE)) | AM7: =IF(ISNA(VLOOKUP(AL7&AK7,benhVien,3,FALSE)),"",VLOOKUP(AL7&AK7,benhVien,3,FALSE)) -> 0 | AO7: =IF(ISNA(VLOOKUP(AN7,tinh,2,FALSE)),"",VLOOKUP(AN7,tinh,2,FALSE)) | AQ7: =IF(ISNA(VLOOKUP(AP7&AO7,huyen,3,FALSE)),"",VLOOKUP(AP7&AO7,huyen,3,FALSE)) | AS7: =IF(ISNA(VLOOKUP(AR7&AQ7,xa,3,FALSE)),"",VLOOKUP(AR7&AQ7,xa,3,FALSE)) -> #REF! | AU7: =IF(ISNA(VLOOKUP(AT7,tinh,2,FALSE)),"",VLOOKUP(AT7,tinh,2,FALSE)) | AW7: =IF(ISNA(VLOOKUP(AV7&AU7,huyen,3,FALSE)),"",VLOOKUP(AV7&AU7,huyen,3,FALSE)) | AY7: =IF(ISNA(VLOOKUP(AX7&AW7,xa,3,FALSE)),"",VLOOKUP(AX7&AW7,xa,3,FALSE)) -> #REF! | CB7: =IF(ISNA(VLOOKUP(CA7,tinh,2,FALSE)),"",VLOOKUP(CA7,tinh,2,FALSE)) | CD7: =IF(ISNA(VLOOKUP(CC7&CB7,huyen,3,FALSE)),"",VLOOKUP(CC7&CB7,huyen,3,FALSE))
E8: =IF(ISNA(VLOOKUP(D8,'Tổng hợp '!$B$25:$C$29,2,FALSE)),"",VLOOKUP(D8,'Tổng hợp '!$B$25:$C$29,2,FALSE)) | G8: =IF(ISNA(VLOOKUP(F8,phuong_an,2,FALSE)),"",VLOOKUP(F8,phuong_an,2,FALSE)) | AG8: =IF(ISNA(VLOOKUP(AF8,quocTich,2,FALSE)),"",VLOOKUP(AF8,quocTich,2,FALSE)) | AI8: =IF(ISNA(VLOOKUP(AH8,danToc,2,FALSE)),"",VLOOKUP(AH8,danToc,2,FALSE)) | AK8: =IF(ISNA(VLOOKUP(AJ8,TinhBenhVien!A:B,2,FALSE)),"",VLOOKUP(AJ8,TinhBenhVien!A:B,2,FALSE)) | AM8: =IF(ISNA(VLOOKUP(AL8&AK8,benhVien,3,FALSE)),"",VLOOKUP(AL8&AK8,benhVien,3,FALSE)) -> 0 | AO8: =IF(ISNA(VLOOKUP(AN8,tinh,2,FALSE)),"",VLOOKUP(AN8,tinh,2,FALSE)) | AQ8: =IF(ISNA(VLOOKUP(AP8&AO8,huyen,3,FALSE)),"",VLOOKUP(AP8&AO8,huyen,3,FALSE)) | AS8: =IF(ISNA(VLOOKUP(AR8&AQ8,xa,3,FALSE)),"",VLOOKUP(AR8&AQ8,xa,3,FALSE)) -> #REF! | AU8: =IF(ISNA(VLOOKUP(AT8,tinh,2,FALSE)),"",VLOOKUP(AT8,tinh,2,FALSE)) | AW8: =IF(ISNA(VLOOKUP(AV8&AU8,huyen,3,FALSE)),"",VLOOKUP(AV8&AU8,huyen,3,FALSE)) | AY8: =IF(ISNA(VLOOKUP(AX8&AW8,xa,3,FALSE)),"",VLOOKUP(AX8&AW8,xa,3,FALSE)) -> #REF! | CB8: =IF(ISNA(VLOOKUP(CA8,tinh,2,FALSE)),"",VLOOKUP(CA8,tinh,2,FALSE)) | CD8: =IF(ISNA(VLOOKUP(CC8&CB8,huyen,3,FALSE)),"",VLOOKUP(CC8&CB8,huyen,3,FALSE))
E9: =IF(ISNA(VLOOKUP(D9,'Tổng hợp '!$B$25:$C$29,2,FALSE)),"",VLOOKUP(D9,'Tổng hợp '!$B$25:$C$29,2,FALSE)) | G9: =IF(ISNA(VLOOKUP(F9,phuong_an,2,FALSE)),"",VLOOKUP(F9,phuong_an,2,FALSE)) | AG9: =IF(ISNA(VLOOKUP(AF9,quocTich,2,FALSE)),"",VLOOKUP(AF9,quocTich,2,FALSE)) | AI9: =IF(ISNA(VLOOKUP(AH9,danToc,2,FALSE)),"",VLOOKUP(AH9,danToc,2,FALSE)) | AK9: =IF(ISNA(VLOOKUP(AJ9,TinhBenhVien!A:B,2,FALSE)),"",VLOOKUP(AJ9,TinhBenhVien!A:B,2,FALSE)) | AM9: =IF(ISNA(VLOOKUP(AL9&AK9,benhVien,3,FALSE)),"",VLOOKUP(AL9&AK9,benhVien,3,FALSE)) -> 0 | AO9: =IF(ISNA(VLOOKUP(AN9,tinh,2,FALSE)),"",VLOOKUP(AN9,tinh,2,FALSE)) | AQ9: =IF(ISNA(VLOOKUP(AP9&AO9,huyen,3,FALSE)),"",VLOOKUP(AP9&AO9,huyen,3,FALSE)) | AS9: =IF(ISNA(VLOOKUP(AR9&AQ9,xa,3,FALSE)),"",VLOOKUP(AR9&AQ9,xa,3,FALSE)) -> #REF! | AU9: =IF(ISNA(VLOOKUP(AT9,tinh,2,FALSE)),"",VLOOKUP(AT9,tinh,2,FALSE)) | AW9: =IF(ISNA(VLOOKUP(AV9&AU9,huyen,3,FALSE)),"",VLOOKUP(AV9&AU9,huyen,3,FALSE)) | AY9: =IF(ISNA(VLOOKUP(AX9&AW9,xa,3,FALSE)),"",VLOOKUP(AX9&AW9,xa,3,FALSE)) -> #REF! | CB9: =IF(ISNA(VLOOKUP(CA9,tinh,2,FALSE)),"",VLOOKUP(CA9,tinh,2,FALSE)) | CD9: =IF(ISNA(VLOOKUP(CC9&CB9,huyen,3,FALSE)),"",VLOOKUP(CC9&CB9,huyen,3,FALSE))
E10: =IF(ISNA(VLOOKUP(D10,'Tổng hợp '!$B$25:$C$29,2,FALSE)),"",VLOOKUP(D10,'Tổng hợp '!$B$25:$C$29,2,FALSE)) | G10: =IF(ISNA(VLOOKUP(F10,phuong_an,2,FALSE)),"",VLOOKUP(F10,phuong_an,2,FALSE)) | AG10: =IF(ISNA(VLOOKUP(AF10,quocTich,2,FALSE)),"",VLOOKUP(AF10,quocTich,2,FALSE)) | AI10: =IF(ISNA(VLOOKUP(AH10,danToc,2,FALSE)),"",VLOOKUP(AH10,danToc,2,FALSE)) | AK10: =IF(ISNA(VLOOKUP(AJ10,TinhBenhVien!A:B,2,FALSE)),"",VLOOKUP(AJ10,TinhBenhVien!A:B,2,FALSE)) | AM10: =IF(ISNA(VLOOKUP(AL10&AK10,benhVien,3,FALSE)),"",VLOOKUP(AL10&AK10,benhVien,3,FALSE)) -> 0 | AO10: =IF(ISNA(VLOOKUP(AN10,tinh,2,FALSE)),"",VLOOKUP(AN10,tinh,2,FALSE)) | AQ10: =IF(ISNA(VLOOKUP(AP10&AO10,huyen,3,FALSE)),"",VLOOKUP(AP10&AO10,huyen,3,FALSE)) | AS10: =IF(ISNA(VLOOKUP(AR10&AQ10,xa,3,FALSE)),"",VLOOKUP(AR10&AQ10,xa,3,FALSE)) -> #REF! | AU10: =IF(ISNA(VLOOKUP(AT10,tinh,2,FALSE)),"",VLOOKUP(AT10,tinh,2,FALSE)) | AW10: =IF(ISNA(VLOOKUP(AV10&AU10,huyen,3,FALSE)),"",VLOOKUP(AV10&AU10,huyen,3,FALSE)) | AY10: =IF(ISNA(VLOOKUP(AX10&AW10,xa,3,FALSE)),"",VLOOKUP(AX10&AW10,xa,3,FALSE)) -> #REF! | CB10: =IF(ISNA(VLOOKUP(CA10,tinh,2,FALSE)),"",VLOOKUP(CA10,tinh,2,FALSE)) | CD10: =IF(ISNA(VLOOKUP(CC10&CB10,huyen,3,FALSE)),"",VLOOKUP(CC10&CB10,huyen,3,FALSE))
E11: =IF(ISNA(VLOOKUP(D11,'Tổng hợp '!$B$25:$C$29,2,FALSE)),"",VLOOKUP(D11,'Tổng hợp '!$B$25:$C$29,2,FALSE)) | G11: =IF(ISNA(VLOOKUP(F11,phuong_an,2,FALSE)),"",VLOOKUP(F11,phuong_an,2,FALSE)) | AG11: =IF(ISNA(VLOOKUP(AF11,quocTich,2,FALSE)),"",VLOOKUP(AF11,quocTich,2,FALSE)) | AI11: =IF(ISNA(VLOOKUP(AH11,danToc,2,FALSE)),"",VLOOKUP(AH11,danToc,2,FALSE)) | AK11: =IF(ISNA(VLOOKUP(AJ11,TinhBenhVien!A:B,2,FALSE)),"",VLOOKUP(AJ11,TinhBenhVien!A:B,2,FALSE)) | AM11: =IF(ISNA(VLOOKUP(AL11&AK11,benhVien,3,FALSE)),"",VLOOKUP(AL11&AK11,benhVien,3,FALSE)) -> 0 | AO11: =IF(ISNA(VLOOKUP(AN11,tinh,2,FALSE)),"",VLOOKUP(AN11,tinh,2,FALSE)) | AQ11: =IF(ISNA(VLOOKUP(AP11&AO11,huyen,3,FALSE)),"",VLOOKUP(AP11&AO11,huyen,3,FALSE)) | AS11: =IF(ISNA(VLOOKUP(AR11&AQ11,xa,3,FALSE)),"",VLOOKUP(AR11&AQ11,xa,3,FALSE)) -> #REF! | AU11: =IF(ISNA(VLOOKUP(AT11,tinh,2,FALSE)),"",VLOOKUP(AT11,tinh,2,FALSE)) | AW11: =IF(ISNA(VLOOKUP(AV11&AU11,huyen,3,FALSE)),"",VLOOKUP(AV11&AU11,huyen,3,FALSE)) | AY11: =IF(ISNA(VLOOKUP(AX11&AW11,xa,3,FALSE)),"",VLOOKUP(AX11&AW11,xa,3,FALSE)) -> #REF! | CB11: =IF(ISNA(VLOOKUP(CA11,tinh,2,FALSE)),"",VLOOKUP(CA11,tinh,2,FALSE)) | CD11: =IF(ISNA(VLOOKUP(CC11&CB11,huyen,3,FALSE)),"",VLOOKUP(CC11&CB11,huyen,3,FALSE))
E12: =IF(ISNA(VLOOKUP(D12,'Tổng hợp '!$B$25:$C$29,2,FALSE)),"",VLOOKUP(D12,'Tổng hợp '!$B$25:$C$29,2,FALSE)) | G12: =IF(ISNA(VLOOKUP(F12,phuong_an,2,FALSE)),"",VLOOKUP(F12,phuong_an,2,FALSE)) | AG12: =IF(ISNA(VLOOKUP(AF12,quocTich,2,FALSE)),"",VLOOKUP(AF12,quocTich,2,FALSE)) | AI12: =IF(ISNA(VLOOKUP(AH12,danToc,2,FALSE)),"",VLOOKUP(AH12,danToc,2,FALSE)) | AK12: =IF(ISNA(VLOOKUP(AJ12,TinhBenhVien!A:B,2,FALSE)),"",VLOOKUP(AJ12,TinhBenhVien!A:B,2,FALSE)) | AM12: =IF(ISNA(VLOOKUP(AL12&AK12,benhVien,3,FALSE)),"",VLOOKUP(AL12&AK12,benhVien,3,FALSE)) -> 0 | AO12: =IF(ISNA(VLOOKUP(AN12,tinh,2,FALSE)),"",VLOOKUP(AN12,tinh,2,FALSE)) | AQ12: =IF(ISNA(VLOOKUP(AP12&AO12,huyen,3,FALSE)),"",VLOOKUP(AP12&AO12,huyen,3,FALSE)) | AS12: =IF(ISNA(VLOOKUP(AR12&AQ12,xa,3,FALSE)),"",VLOOKUP(AR12&AQ12,xa,3,FALSE)) -> #REF! | AU12: =IF(ISNA(VLOOKUP(AT12,tinh,2,FALSE)),"",VLOOKUP(AT12,tinh,2,FALSE)) | AW12: =IF(ISNA(VLOOKUP(AV12&AU12,huyen,3,FALSE)),"",VLOOKUP(AV12&AU12,huyen,3,FALSE)) | AY12: =IF(ISNA(VLOOKUP(AX12&AW12,xa,3,FALSE)),"",VLOOKUP(AX12&AW12,xa,3,FALSE)) -> #REF! | CB12: =IF(ISNA(VLOOKUP(CA12,tinh,2,FALSE)),"",VLOOKUP(CA12,tinh,2,FALSE)) | CD12: =IF(ISNA(VLOOKUP(CC12&CB12,huyen,3,FALSE)),"",VLOOKUP(CC12&CB12,huyen,3,FALSE))
E13: =IF(ISNA(VLOOKUP(D13,'Tổng hợp '!$B$25:$C$29,2,FALSE)),"",VLOOKUP(D13,'Tổng hợp '!$B$25:$C$29,2,FALSE)) | G13: =IF(ISNA(VLOOKUP(F13,phuong_an,2,FALSE)),"",VLOOKUP(F13,phuong_an,2,FALSE)) | AG13: =IF(ISNA(VLOOKUP(AF13,quocTich,2,FALSE)),"",VLOOKUP(AF13,quocTich,2,FALSE)) | AI13: =IF(ISNA(VLOOKUP(AH13,danToc,2,FALSE)),"",VLOOKUP(AH13,danToc,2,FALSE)) | AK13: =IF(ISNA(VLOOKUP(AJ13,TinhBenhVien!A:B,2,FALSE)),"",VLOOKUP(AJ13,TinhBenhVien!A:B,2,FALSE)) | AM13: =IF(ISNA(VLOOKUP(AL13&AK13,benhVien,3,FALSE)),"",VLOOKUP(AL13&AK13,benhVien,3,FALSE)) -> 0 | AO13: =IF(ISNA(VLOOKUP(AN13,tinh,2,FALSE)),"",VLOOKUP(AN13,tinh,2,FALSE)) | AQ13: =IF(ISNA(VLOOKUP(AP13&AO13,huyen,3,FALSE)),"",VLOOKUP(AP13&AO13,huyen,3,FALSE)) | AS13: =IF(ISNA(VLOOKUP(AR13&AQ13,xa,3,FALSE)),"",VLOOKUP(AR13&AQ13,xa,3,FALSE)) -> #REF! | AU13: =IF(ISNA(VLOOKUP(AT13,tinh,2,FALSE)),"",VLOOKUP(AT13,tinh,2,FALSE)) | AW13: =IF(ISNA(VLOOKUP(AV13&AU13,huyen,3,FALSE)),"",VLOOKUP(AV13&AU13,huyen,3,FALSE)) | AY13: =IF(ISNA(VLOOKUP(AX13&AW13,xa,3,FALSE)),"",VLOOKUP(AX13&AW13,xa,3,FALSE)) -> #REF! | CB13: =IF(ISNA(VLOOKUP(CA13,tinh,2,FALSE)),"",VLOOKUP(CA13,tinh,2,FALSE)) | CD13: =IF(ISNA(VLOOKUP(CC13&CB13,huyen,3,FALSE)),"",VLOOKUP(CC13&CB13,huyen,3,FALSE))
E14: =IF(ISNA(VLOOKUP(D14,'Tổng hợp '!$B$25:$C$29,2,FALSE)),"",VLOOKUP(D14,'Tổng hợp '!$B$25:$C$29,2,FALSE)) | G14: =IF(ISNA(VLOOKUP(F14,phuong_an,2,FALSE)),"",VLOOKUP(F14,phuong_an,2,FALSE)) | AG14: =IF(ISNA(VLOOKUP(AF14,quocTich,2,FALSE)),"",VLOOKUP(AF14,quocTich,2,FALSE)) | AI14: =IF(ISNA(VLOOKUP(AH14,danToc,2,FALSE)),"",VLOOKUP(AH14,danToc,2,FALSE)) | AK14: =IF(ISNA(VLOOKUP(AJ14,TinhBenhVien!A:B,2,FALSE)),"",VLOOKUP(AJ14,TinhBenhVien!A:B,2,FALSE)) | AM14: =IF(ISNA(VLOOKUP(AL14&AK14,benhVien,3,FALSE)),"",VLOOKUP(AL14&AK14,benhVien,3,FALSE)) -> 0 | AO14: =IF(ISNA(VLOOKUP(AN14,tinh,2,FALSE)),"",VLOOKUP(AN14,tinh,2,FALSE)) | AQ14: =IF(ISNA(VLOOKUP(AP14&AO14,huyen,3,FALSE)),"",VLOOKUP(AP14&AO14,huyen,3,FALSE)) | AS14: =IF(ISNA(VLOOKUP(AR14&AQ14,xa,3,FALSE)),"",VLOOKUP(AR14&AQ14,xa,3,FALSE)) -> #REF! | AU14: =IF(ISNA(VLOOKUP(AT14,tinh,2,FALSE)),"",VLOOKUP(AT14,tinh,2,FALSE)) | AW14: =IF(ISNA(VLOOKUP(AV14&AU14,huyen,3,FALSE)),"",VLOOKUP(AV14&AU14,huyen,3,FALSE)) | AY14: =IF(ISNA(VLOOKUP(AX14&AW14,xa,3,FALSE)),"",VLOOKUP(AX14&AW14,xa,3,FALSE)) -> #REF! | CB14: =IF(ISNA(VLOOKUP(CA14,tinh,2,FALSE)),"",VLOOKUP(CA14,tinh,2,FALSE)) | CD14: =IF(ISNA(VLOOKUP(CC14&CB14,huyen,3,FALSE)),"",VLOOKUP(CC14&CB14,huyen,3,FALSE))
E15: =IF(ISNA(VLOOKUP(D15,'Tổng hợp '!$B$25:$C$29,2,FALSE)),"",VLOOKUP(D15,'Tổng hợp '!$B$25:$C$29,2,FALSE)) | G15: =IF(ISNA(VLOOKUP(F15,phuong_an,2,FALSE)),"",VLOOKUP(F15,phuong_an,2,FALSE)) | AG15: =IF(ISNA(VLOOKUP(AF15,quocTich,2,FALSE)),"",VLOOKUP(AF15,quocTich,2,FALSE)) | AI15: =IF(ISNA(VLOOKUP(AH15,danToc,2,FALSE)),"",VLOOKUP(AH15,danToc,2,FALSE)) | AK15: =IF(ISNA(VLOOKUP(AJ15,TinhBenhVien!A:B,2,FALSE)),"",VLOOKUP(AJ15,TinhBenhVien!A:B,2,FALSE)) | AM15: =IF(ISNA(VLOOKUP(AL15&AK15,benhVien,3,FALSE)),"",VLOOKUP(AL15&AK15,benhVien,3,FALSE)) -> 0 | AO15: =IF(ISNA(VLOOKUP(AN15,tinh,2,FALSE)),"",VLOOKUP(AN15,tinh,2,FALSE)) | AQ15: =IF(ISNA(VLOOKUP(AP15&AO15,huyen,3,FALSE)),"",VLOOKUP(AP15&AO15,huyen,3,FALSE)) | AS15: =IF(ISNA(VLOOKUP(AR15&AQ15,xa,3,FALSE)),"",VLOOKUP(AR15&AQ15,xa,3,FALSE)) -> #REF! | AU15: =IF(ISNA(VLOOKUP(AT15,tinh,2,FALSE)),"",VLOOKUP(AT15,tinh,2,FALSE)) | AW15: =IF(ISNA(VLOOKUP(AV15&AU15,huyen,3,FALSE)),"",VLOOKUP(AV15&AU15,huyen,3,FALSE)) | AY15: =IF(ISNA(VLOOKUP(AX15&AW15,xa,3,FALSE)),"",VLOOKUP(AX15&AW15,xa,3,FALSE)) -> #REF! | CB15: =IF(ISNA(VLOOKUP(CA15,tinh,2,FALSE)),"",VLOOKUP(CA15,tinh,2,FALSE)) | CD15: =IF(ISNA(VLOOKUP(CC15&CB15,huyen,3,FALSE)),"",VLOOKUP(CC15&CB15,huyen,3,FALSE))
E16: =IF(ISNA(VLOOKUP(D16,'Tổng hợp '!$B$25:$C$29,2,FALSE)),"",VLOOKUP(D16,'Tổng hợp '!$B$25:$C$29,2,FALSE)) | G16: =IF(ISNA(VLOOKUP(F16,phuong_an,2,FALSE)),"",VLOOKUP(F16,phuong_an,2,FALSE)) | AG16: =IF(ISNA(VLOOKUP(AF16,quocTich,2,FALSE)),"",VLOOKUP(AF16,quocTich,2,FALSE)) | AI16: =IF(ISNA(VLOOKUP(AH16,danToc,2,FALSE)),"",VLOOKUP(AH16,danToc,2,FALSE)) | AK16: =IF(ISNA(VLOOKUP(AJ16,TinhBenhVien!A:B,2,FALSE)),"",VLOOKUP(AJ16,TinhBenhVien!A:B,2,FALSE)) | AM16: =IF(ISNA(VLOOKUP(AL16&AK16,benhVien,3,FALSE)),"",VLOOKUP(AL16&AK16,benhVien,3,FALSE)) -> 0 | AO16: =IF(ISNA(VLOOKUP(AN16,tinh,2,FALSE)),"",VLOOKUP(AN16,tinh,2,FALSE)) | AQ16: =IF(ISNA(VLOOKUP(AP16&AO16,huyen,3,FALSE)),"",VLOOKUP(AP16&AO16,huyen,3,FALSE)) | AS16: =IF(ISNA(VLOOKUP(AR16&AQ16,xa,3,FALSE)),"",VLOOKUP(AR16&AQ16,xa,3,FALSE)) -> #REF! | AU16: =IF(ISNA(VLOOKUP(AT16,tinh,2,FALSE)),"",VLOOKUP(AT16,tinh,2,FALSE)) | AW16: =IF(ISNA(VLOOKUP(AV16&AU16,huyen,3,FALSE)),"",VLOOKUP(AV16&AU16,huyen,3,FALSE)) | AY16: =IF(ISNA(VLOOKUP(AX16&AW16,xa,3,FALSE)),"",VLOOKUP(AX16&AW16,xa,3,FALSE)) -> #REF! | CB16: =IF(ISNA(VLOOKUP(CA16,tinh,2,FALSE)),"",VLOOKUP(CA16,tinh,2,FALSE)) | CD16: =IF(ISNA(VLOOKUP(CC16&CB16,huyen,3,FALSE)),"",VLOOKUP(CC16&CB16,huyen,3,FALSE))
E17: =IF(ISNA(VLOOKUP(D17,'Tổng hợp '!$B$25:$C$29,2,FALSE)),"",VLOOKUP(D17,'Tổng hợp '!$B$25:$C$29,2,FALSE)) | G17: =IF(ISNA(VLOOKUP(F17,phuong_an,2,FALSE)),"",VLOOKUP(F17,phuong_an,2,FALSE)) | AG17: =IF(ISNA(VLOOKUP(AF17,quocTich,2,FALSE)),"",VLOOKUP(AF17,quocTich,2,FALSE)) | AI17: =IF(ISNA(VLOOKUP(AH17,danToc,2,FALSE)),"",VLOOKUP(AH17,danToc,2,FALSE)) | AK17: =IF(ISNA(VLOOKUP(AJ17,TinhBenhVien!A:B,2,FALSE)),"",VLOOKUP(AJ17,TinhBenhVien!A:B,2,FALSE)) | AM17: =IF(ISNA(VLOOKUP(AL17&AK17,benhVien,3,FALSE)),"",VLOOKUP(AL17&AK17,benhVien,3,FALSE)) -> 0 | AO17: =IF(ISNA(VLOOKUP(AN17,tinh,2,FALSE)),"",VLOOKUP(AN17,tinh,2,FALSE)) | AQ17: =IF(ISNA(VLOOKUP(AP17&AO17,huyen,3,FALSE)),"",VLOOKUP(AP17&AO17,huyen,3,FALSE)) | AS17: =IF(ISNA(VLOOKUP(AR17&AQ17,xa,3,FALSE)),"",VLOOKUP(AR17&AQ17,xa,3,FALSE)) -> #REF! | AU17: =IF(ISNA(VLOOKUP(AT17,tinh,2,FALSE)),"",VLOOKUP(AT17,tinh,2,FALSE)) | AW17: =IF(ISNA(VLOOKUP(AV17&AU17,huyen,3,FALSE)),"",VLOOKUP(AV17&AU17,huyen,3,FALSE)) | AY17: =IF(ISNA(VLOOKUP(AX17&AW17,xa,3,FALSE)),"",VLOOKUP(AX17&AW17,xa,3,FALSE)) -> #REF! | CB17: =IF(ISNA(VLOOKUP(CA17,tinh,2,FALSE)),"",VLOOKUP(CA17,tinh,2,FALSE)) | CD17: =IF(ISNA(VLOOKUP(CC17&CB17,huyen,3,FALSE)),"",VLOOKUP(CC17&CB17,huyen,3,FALSE))
E18: =IF(ISNA(VLOOKUP(D18,'Tổng hợp '!$B$25:$C$29,2,FALSE)),"",VLOOKUP(D18,'Tổng hợp '!$B$25:$C$29,2,FALSE)) | G18: =IF(ISNA(VLOOKUP(F18,phuong_an,2,FALSE)),"",VLOOKUP(F18,phuong_an,2,FALSE)) | AG18: =IF(ISNA(VLOOKUP(AF18,quocTich,2,FALSE)),"",VLOOKUP(AF18,quocTich,2,FALSE)) | AI18: =IF(ISNA(VLOOKUP(AH18,danToc,2,FALSE)),"",VLOOKUP(AH18,danToc,2,FALSE)) | AK18: =IF(ISNA(VLOOKUP(AJ18,TinhBenhVien!A:B,2,FALSE)),"",VLOOKUP(AJ18,TinhBenhVien!A:B,2,FALSE)) | AM18: =IF(ISNA(VLOOKUP(AL18&AK18,benhVien,3,FALSE)),"",VLOOKUP(AL18&AK18,benhVien,3,FALSE)) -> 0 | AO18: =IF(ISNA(VLOOKUP(AN18,tinh,2,FALSE)),"",VLOOKUP(AN18,tinh,2,FALSE)) | AQ18: =IF(ISNA(VLOOKUP(AP18&AO18,huyen,3,FALSE)),"",VLOOKUP(AP18&AO18,huyen,3,FALSE)) | AS18: =IF(ISNA(VLOOKUP(AR18&AQ18,xa,3,FALSE)),"",VLOOKUP(AR18&AQ18,xa,3,FALSE)) -> #REF! | AU18: =IF(ISNA(VLOOKUP(AT18,tinh,2,FALSE)),"",VLOOKUP(AT18,tinh,2,FALSE)) | AW18: =IF(ISNA(VLOOKUP(AV18&AU18,huyen,3,FALSE)),"",VLOOKUP(AV18&AU18,huyen,3,FALSE)) | AY18: =IF(ISNA(VLOOKUP(AX18&AW18,xa,3,FALSE)),"",VLOOKUP(AX18&AW18,xa,3,FALSE)) -> #REF! | CB18: =IF(ISNA(VLOOKUP(CA18,tinh,2,FALSE)),"",VLOOKUP(CA18,tinh,2,FALSE)) | CD18: =IF(ISNA(VLOOKUP(CC18&CB18,huyen,3,FALSE)),"",VLOOKUP(CC18&CB18,huyen,3,FALSE))
... E1078: =IF(ISNA(VLOOKUP(D1078,'Tổng hợp '!$B$25:$C$29,2,FALSE)),"",VLOOKUP(D1078,'Tổng hợp '!$B$25:$C$29,2,FALSE)) | G1078: =IF(ISNA(VLOOKUP(F1078,phuong_an,2,FALSE)),"",VLOOKUP(F1078,phuong_an,2,FALSE)) | AG1078: =IF(ISNA(VLOOKUP(AF1078,quocTich,2,FALSE)),"",VLOOKUP(AF1078,quocTich,2,FALSE)) | AI1078: =IF(ISNA(VLOOKUP(AH1078,danToc,2,FALSE)),"",VLOOKUP(AH1078,danToc,2,FALSE)) | AK1078: =IF(ISNA(VLOOKUP(AJ1078,TinhBenhVien!A:B,2,FALSE)),"",VLOOKUP(AJ1078,TinhBenhVien!A:B,2,FALSE)) | AM1078: =IF(ISNA(VLOOKUP(AL1078&AK1078,benhVien,3,FALSE)),"",VLOOKUP(AL1078&AK1078,benhVien,3,FALSE)) -> 0 | AO1078: =IF(ISNA(VLOOKUP(AN1078,tinh,2,FALSE)),"",VLOOKUP(AN1078,tinh,2,FALSE)) | AQ1078: =IF(ISNA(VLOOKUP(AP1078&AO1078,huyen,3,FALSE)),"",VLOOKUP(AP1078&AO1078,huyen,3,FALSE)) | AS1078: =IF(ISNA(VLOOKUP(AR1078&AQ1078,xa,3,FALSE)),"",VLOOKUP(AR1078&AQ1078,xa,3,FALSE)) -> #REF! | AU1078: =IF(ISNA(VLOOKUP(AT1078,tinh,2,FALSE)),"",VLOOKUP(AT1078,tinh,2,FALSE)) | AW1078: =IF(ISNA(VLOOKUP(AV1078&AU1078,huyen,3,FALSE)),"",VLOOKUP(AV1078&AU1078,huyen,3,FALSE)) | AY1078: =IF(ISNA(VLOOKUP(AX1078&AW1078,xa,3,FALSE)),"",VLOOKUP(AX1078&AW1078,xa,3,FALSE)) -> #REF! | CB1078: =IF(ISNA(VLOOKUP(CA1078,tinh,2,FALSE)),"",VLOOKUP(CA1078,tinh,2,FALSE)) | CD1078: =IF(ISNA(VLOOKUP(CC1078&CB1078,huyen,3,FALSE)),"",VLOOKUP(CC1078&CB1078,huyen,3,FALSE))

Sheet Phụ lục
B1: THÔNG TIN THÀNH VIÊN (Bao gồm cả người tham gia và chủ hộ)
A2: ID Lao động lấy ở Sheet Dữ Liệu | B2: Họ tên Thành viên | C2: Mã số BHXH | D2: Ngày sinh (tháng/năm hoặc năm sinh) | E2: Giới tính | F2: Tỉnh khai sinh | G2: Mã tỉnh khai sinh | H2: Xã khai sinh | I2: Mã xã khai sinh | J2: Xã khai sinh | K2: Mã xã khai sinh | L2: Tên Thôn/Xóm | M2: Mối quan hệ | N2: Mã quan hệ | O2: Số CMND của thành viên | P2: Ghi chú | Q2: Người tham gia (0: Không 1: Có) | R2: Số điện thoại | S2: Loại giấy tờ | T2: Số giấy tờ | U2: Quốc tịch | V2: Dân tộc | W2: Tỉnh hộ khẩu | X2: Mã tỉnh hộ khẩu | Y2: Xã hộ khẩu | Z2: Mã xã khai sinh | AA2: Xã hộ khẩu | AB2: Mã xã khai sinh | AC2: Mã số hộ gia đình | AD2: Địa chỉ hộ khẩu | AE2: Địa chỉ đăng ký khai sinh | AF2: Địa chỉ thường trú | AG2: Tỉnh thường trú | AH2: Mã tỉnh thường trú | AI2: Xã thường trú | AJ2: Mã xã thường trú | AK2: Xã thường trú | AL2: Mã xã thường trú | AM2: Số CCCD/ĐDCN chủ hộ
A3: STT | B3: HoTen | C3: MasoBHXH | D3: NgaySinh | E3: GioiTinh | F3: TenTinhKS | G3: Matinh_KS | H3: TenXaKS | I3: Maxa_KS | L3: MaThon | M3: TenMoiQuanHe | N3: MoiQuanHe | O3: CMND | P3: Ghichu | Q3: NguoiThamGia | R3: DienThoai | S3: LoaiGiayTo | T3: SoGiayTo | U3: QuocTich | V3: DanToc | W3: TenTinh | X3: Matinh | Y3: TenXa | Z3: Maxa | AC3: Maso_HoGiadinh | AD3: Diachi_HK | AE3: DiachiDK_KS | AF3: Diachi_TT_CH | AG3: TenTinh_TT_CH | AH3: Tinh_TT_CH | AI3: TenXa_TT_CH | AJ3: Xa_TT_CH | AM3: SoCCCD_CH
A4: 1 | B4: Bùi Văn A | C4: 1234567890 | D4: 1990 | E4: 1 | F4: Thành phố Hà Nội | G4: =IF(ISNA(VLOOKUP(F4,tinh,2,FALSE)),"",VLOOKUP(F4,tinh,2,FALSE)) -> 01 | H4: Quận Hoàn Kiếm | I4: =IF(ISNA(VLOOKUP(H4&G4,huyen,3,FALSE)),"",VLOOKUP(H4&G4,huyen,3,FALSE)) | J4: Xã Trường Hà | K4: =IF(ISNA(VLOOKUP(J4&I4,xa,3,FALSE)),"",VLOOKUP(J4&I4,xa,3,FALSE)) -> #REF! | M4: Chủ hộ | N4: =IF(ISNA(VLOOKUP(M4,ma_mqh,2,FALSE)),"",VLOOKUP(M4,ma_mqh,2,FALSE)) -> 00 | Q4: 1 | S4: 1 | U4: VN | V4: 01 | W4: Tỉnh Tuyên Quang | X4: =IF(ISNA(VLOOKUP(W4,tinh,2,FALSE)),"",VLOOKUP(W4,tinh,2,FALSE)) -> 08 | Y4: Huyện Na Hang | Z4: =IF(ISNA(VLOOKUP(Y4&X4,huyen,3,FALSE)),"",VLOOKUP(Y4&X4,huyen,3,FALSE)) | AA4: Xã Thượng Giáp | AB4: =IF(ISNA(VLOOKUP(AA4&Z4,xa,3,FALSE)),"",VLOOKUP(AA4&Z4,xa,3,FALSE)) -> #REF! | AC4: 11313232 | AD4: Tòa nhà Internet | AE4: Tòa nhà Internet | AF4: Tòa nhà Internet | AG4: Tỉnh Tuyên Quang | AH4: =IF(ISNA(VLOOKUP(AG4,tinh,2,FALSE)),"",VLOOKUP(AG4,tinh,2,FALSE)) -> 08 | AI4: Huyện Na Hang | AJ4: =IF(ISNA(VLOOKUP(AI4&AH4,huyen,3,FALSE)),"",VLOOKUP(AI4&AH4,huyen,3,FALSE)) | AK4: Xã Thượng Giáp | AL4: =IF(ISNA(VLOOKUP(AK4&AJ4,xa,3,FALSE)),"",VLOOKUP(AK4&AJ4,xa,3,FALSE)) -> #REF! | AM4: 001298765432
G5: =IF(ISNA(VLOOKUP(F5,tinh,2,FALSE)),"",VLOOKUP(F5,tinh,2,FALSE)) | I5: =IF(ISNA(VLOOKUP(H5&G5,huyen,3,FALSE)),"",VLOOKUP(H5&G5,huyen,3,FALSE)) | K5: =IF(ISNA(VLOOKUP(J5&I5,xa,3,FALSE)),"",VLOOKUP(J5&I5,xa,3,FALSE)) -> #REF! | N5: =IF(ISNA(VLOOKUP(M5,ma_mqh,2,FALSE)),"",VLOOKUP(M5,ma_mqh,2,FALSE)) | X5: =IF(ISNA(VLOOKUP(W5,tinh,2,FALSE)),"",VLOOKUP(W5,tinh,2,FALSE)) | Z5: =IF(ISNA(VLOOKUP(Y5&X5,huyen,3,FALSE)),"",VLOOKUP(Y5&X5,huyen,3,FALSE)) | AB5: =IF(ISNA(VLOOKUP(AA5&Z5,xa,3,FALSE)),"",VLOOKUP(AA5&Z5,xa,3,FALSE)) -> #REF! | AH5: =IF(ISNA(VLOOKUP(AG5,tinh,2,FALSE)),"",VLOOKUP(AG5,tinh,2,FALSE)) | AJ5: =IF(ISNA(VLOOKUP(AI5&AH5,huyen,3,FALSE)),"",VLOOKUP(AI5&AH5,huyen,3,FALSE)) | AL5: =IF(ISNA(VLOOKUP(AK5&AJ5,xa,3,FALSE)),"",VLOOKUP(AK5&AJ5,xa,3,FALSE)) -> #REF!
G6: =IF(ISNA(VLOOKUP(F6,tinh,2,FALSE)),"",VLOOKUP(F6,tinh,2,FALSE)) | I6: =IF(ISNA(VLOOKUP(H6&G6,huyen,3,FALSE)),"",VLOOKUP(H6&G6,huyen,3,FALSE)) | K6: =IF(ISNA(VLOOKUP(J6&I6,xa,3,FALSE)),"",VLOOKUP(J6&I6,xa,3,FALSE)) -> #REF! | N6: =IF(ISNA(VLOOKUP(M6,ma_mqh,2,FALSE)),"",VLOOKUP(M6,ma_mqh,2,FALSE)) | X6: =IF(ISNA(VLOOKUP(W6,tinh,2,FALSE)),"",VLOOKUP(W6,tinh,2,FALSE)) | Z6: =IF(ISNA(VLOOKUP(Y6&X6,huyen,3,FALSE)),"",VLOOKUP(Y6&X6,huyen,3,FALSE)) | AB6: =IF(ISNA(VLOOKUP(AA6&Z6,xa,3,FALSE)),"",VLOOKUP(AA6&Z6,xa,3,FALSE)) -> #REF! | AH6: =IF(ISNA(VLOOKUP(AG6,tinh,2,FALSE)),"",VLOOKUP(AG6,tinh,2,FALSE)) | AJ6: =IF(ISNA(VLOOKUP(AI6&AH6,huyen,3,FALSE)),"",VLOOKUP(AI6&AH6,huyen,3,FALSE)) | AL6: =IF(ISNA(VLOOKUP(AK6&AJ6,xa,3,FALSE)),"",VLOOKUP(AK6&AJ6,xa,3,FALSE)) -> #REF!
G7: =IF(ISNA(VLOOKUP(F7,tinh,2,FALSE)),"",VLOOKUP(F7,tinh,2,FALSE)) | I7: =IF(ISNA(VLOOKUP(H7&G7,huyen,3,FALSE)),"",VLOOKUP(H7&G7,huyen,3,FALSE)) | K7: =IF(ISNA(VLOOKUP(J7&I7,xa,3,FALSE)),"",VLOOKUP(J7&I7,xa,3,FALSE)) -> #REF! | N7: =IF(ISNA(VLOOKUP(M7,ma_mqh,2,FALSE)),"",VLOOKUP(M7,ma_mqh,2,FALSE)) | X7: =IF(ISNA(VLOOKUP(W7,tinh,2,FALSE)),"",VLOOKUP(W7,tinh,2,FALSE)) | Z7: =IF(ISNA(VLOOKUP(Y7&X7,huyen,3,FALSE)),"",VLOOKUP(Y7&X7,huyen,3,FALSE)) | AB7: =IF(ISNA(VLOOKUP(AA7&Z7,xa,3,FALSE)),"",VLOOKUP(AA7&Z7,xa,3,FALSE)) -> #REF! | AH7: =IF(ISNA(VLOOKUP(AG7,tinh,2,FALSE)),"",VLOOKUP(AG7,tinh,2,FALSE)) | AJ7: =IF(ISNA(VLOOKUP(AI7&AH7,huyen,3,FALSE)),"",VLOOKUP(AI7&AH7,huyen,3,FALSE)) | AL7: =IF(ISNA(VLOOKUP(AK7&AJ7,xa,3,FALSE)),"",VLOOKUP(AK7&AJ7,xa,3,FALSE)) -> #REF!
G8: =IF(ISNA(VLOOKUP(F8,tinh,2,FALSE)),"",VLOOKUP(F8,tinh,2,FALSE)) | I8: =IF(ISNA(VLOOKUP(H8&G8,huyen,3,FALSE)),"",VLOOKUP(H8&G8,huyen,3,FALSE)) | K8: =IF(ISNA(VLOOKUP(J8&I8,xa,3,FALSE)),"",VLOOKUP(J8&I8,xa,3,FALSE)) -> #REF! | N8: =IF(ISNA(VLOOKUP(M8,ma_mqh,2,FALSE)),"",VLOOKUP(M8,ma_mqh,2,FALSE)) | X8: =IF(ISNA(VLOOKUP(W8,tinh,2,FALSE)),"",VLOOKUP(W8,tinh,2,FALSE)) | Z8: =IF(ISNA(VLOOKUP(Y8&X8,huyen,3,FALSE)),"",VLOOKUP(Y8&X8,huyen,3,FALSE)) | AB8: =IF(ISNA(VLOOKUP(AA8&Z8,xa,3,FALSE)),"",VLOOKUP(AA8&Z8,xa,3,FALSE)) -> #REF! | AH8: =IF(ISNA(VLOOKUP(AG8,tinh,2,FALSE)),"",VLOOKUP(AG8,tinh,2,FALSE)) | AJ8: =IF(ISNA(VLOOKUP(AI8&AH8,huyen,3,FALSE)),"",VLOOKUP(AI8&AH8,huyen,3,FALSE)) | AL8: =IF(ISNA(VLOOKUP(AK8&AJ8,xa,3,FALSE)),"",VLOOKUP(AK8&AJ8,xa,3,FALSE)) -> #REF!
G9: =IF(ISNA(VLOOKUP(F9,tinh,2,FALSE)),"",VLOOKUP(F9,tinh,2,FALSE)) | I9: =IF(ISNA(VLOOKUP(H9&G9,huyen,3,FALSE)),"",VLOOKUP(H9&G9,huyen,3,FALSE)) | K9: =IF(ISNA(VLOOKUP(J9&I9,xa,3,FALSE)),"",VLOOKUP(J9&I9,xa,3,FALSE)) -> #REF! | N9: =IF(ISNA(VLOOKUP(M9,ma_mqh,2,FALSE)),"",VLOOKUP(M9,ma_mqh,2,FALSE)) | X9: =IF(ISNA(VLOOKUP(W9,tinh,2,FALSE)),"",VLOOKUP(W9,tinh,2,FALSE)) | Z9: =IF(ISNA(VLOOKUP(Y9&X9,huyen,3,FALSE)),"",VLOOKUP(Y9&X9,huyen,3,FALSE)) | AB9: =IF(ISNA(VLOOKUP(AA9&Z9,xa,3,FALSE)),"",VLOOKUP(AA9&Z9,xa,3,FALSE)) -> #REF! | AH9: =IF(ISNA(VLOOKUP(AG9,tinh,2,FALSE)),"",VLOOKUP(AG9,tinh,2,FALSE)) | AJ9: =IF(ISNA(VLOOKUP(AI9&AH9,huyen,3,FALSE)),"",VLOOKUP(AI9&AH9,huyen,3,FALSE)) | AL9: =IF(ISNA(VLOOKUP(AK9&AJ9,xa,3,FALSE)),"",VLOOKUP(AK9&AJ9,xa,3,FALSE)) -> #REF!
G10: =IF(ISNA(VLOOKUP(F10,tinh,2,FALSE)),"",VLOOKUP(F10,tinh,2,FALSE)) | I10: =IF(ISNA(VLOOKUP(H10&G10,huyen,3,FALSE)),"",VLOOKUP(H10&G10,huyen,3,FALSE)) | K10: =IF(ISNA(VLOOKUP(J10&I10,xa,3,FALSE)),"",VLOOKUP(J10&I10,xa,3,FALSE)) -> #REF! | N10: =IF(ISNA(VLOOKUP(M10,ma_mqh,2,FALSE)),"",VLOOKUP(M10,ma_mqh,2,FALSE)) | X10: =IF(ISNA(VLOOKUP(W10,tinh,2,FALSE)),"",VLOOKUP(W10,tinh,2,FALSE)) | Z10: =IF(ISNA(VLOOKUP(Y10&X10,huyen,3,FALSE)),"",VLOOKUP(Y10&X10,huyen,3,FALSE)) | AB10: =IF(ISNA(VLOOKUP(AA10&Z10,xa,3,FALSE)),"",VLOOKUP(AA10&Z10,xa,3,FALSE)) -> #REF! | AH10: =IF(ISNA(VLOOKUP(AG10,tinh,2,FALSE)),"",VLOOKUP(AG10,tinh,2,FALSE)) | AJ10: =IF(ISNA(VLOOKUP(AI10&AH10,huyen,3,FALSE)),"",VLOOKUP(AI10&AH10,huyen,3,FALSE)) | AL10: =IF(ISNA(VLOOKUP(AK10&AJ10,xa,3,FALSE)),"",VLOOKUP(AK10&AJ10,xa,3,FALSE)) -> #REF!
G11: =IF(ISNA(VLOOKUP(F11,tinh,2,FALSE)),"",VLOOKUP(F11,tinh,2,FALSE)) | I11: =IF(ISNA(VLOOKUP(H11&G11,huyen,3,FALSE)),"",VLOOKUP(H11&G11,huyen,3,FALSE)) | K11: =IF(ISNA(VLOOKUP(J11&I11,xa,3,FALSE)),"",VLOOKUP(J11&I11,xa,3,FALSE)) -> #REF! | N11: =IF(ISNA(VLOOKUP(M11,ma_mqh,2,FALSE)),"",VLOOKUP(M11,ma_mqh,2,FALSE)) | X11: =IF(ISNA(VLOOKUP(W11,tinh,2,FALSE)),"",VLOOKUP(W11,tinh,2,FALSE)) | Z11: =IF(ISNA(VLOOKUP(Y11&X11,huyen,3,FALSE)),"",VLOOKUP(Y11&X11,huyen,3,FALSE)) | AB11: =IF(ISNA(VLOOKUP(AA11&Z11,xa,3,FALSE)),"",VLOOKUP(AA11&Z11,xa,3,FALSE)) -> #REF! | AH11: =IF(ISNA(VLOOKUP(AG11,tinh,2,FALSE)),"",VLOOKUP(AG11,tinh,2,FALSE)) | AJ11: =IF(ISNA(VLOOKUP(AI11&AH11,huyen,3,FALSE)),"",VLOOKUP(AI11&AH11,huyen,3,FALSE)) | AL11: =IF(ISNA(VLOOKUP(AK11&AJ11,xa,3,FALSE)),"",VLOOKUP(AK11&AJ11,xa,3,FALSE)) -> #REF!
G12: =IF(ISNA(VLOOKUP(F12,tinh,2,FALSE)),"",VLOOKUP(F12,tinh,2,FALSE)) | I12: =IF(ISNA(VLOOKUP(H12&G12,huyen,3,FALSE)),"",VLOOKUP(H12&G12,huyen,3,FALSE)) | K12: =IF(ISNA(VLOOKUP(J12&I12,xa,3,FALSE)),"",VLOOKUP(J12&I12,xa,3,FALSE)) -> #REF! | N12: =IF(ISNA(VLOOKUP(M12,ma_mqh,2,FALSE)),"",VLOOKUP(M12,ma_mqh,2,FALSE)) | X12: =IF(ISNA(VLOOKUP(W12,tinh,2,FALSE)),"",VLOOKUP(W12,tinh,2,FALSE)) | Z12: =IF(ISNA(VLOOKUP(Y12&X12,huyen,3,FALSE)),"",VLOOKUP(Y12&X12,huyen,3,FALSE)) | AB12: =IF(ISNA(VLOOKUP(AA12&Z12,xa,3,FALSE)),"",VLOOKUP(AA12&Z12,xa,3,FALSE)) -> #REF! | AH12: =IF(ISNA(VLOOKUP(AG12,tinh,2,FALSE)),"",VLOOKUP(AG12,tinh,2,FALSE)) | AJ12: =IF(ISNA(VLOOKUP(AI12&AH12,huyen,3,FALSE)),"",VLOOKUP(AI12&AH12,huyen,3,FALSE)) | AL12: =IF(ISNA(VLOOKUP(AK12&AJ12,xa,3,FALSE)),"",VLOOKUP(AK12&AJ12,xa,3,FALSE)) -> #REF!
G13: =IF(ISNA(VLOOKUP(F13,tinh,2,FALSE)),"",VLOOKUP(F13,tinh,2,FALSE)) | I13: =IF(ISNA(VLOOKUP(H13&G13,huyen,3,FALSE)),"",VLOOKUP(H13&G13,huyen,3,FALSE)) | K13: =IF(ISNA(VLOOKUP(J13&I13,xa,3,FALSE)),"",VLOOKUP(J13&I13,xa,3,FALSE)) -> #REF! | N13: =IF(ISNA(VLOOKUP(M13,ma_mqh,2,FALSE)),"",VLOOKUP(M13,ma_mqh,2,FALSE)) | X13: =IF(ISNA(VLOOKUP(W13,tinh,2,FALSE)),"",VLOOKUP(W13,tinh,2,FALSE)) | Z13: =IF(ISNA(VLOOKUP(Y13&X13,huyen,3,FALSE)),"",VLOOKUP(Y13&X13,huyen,3,FALSE)) | AB13: =IF(ISNA(VLOOKUP(AA13&Z13,xa,3,FALSE)),"",VLOOKUP(AA13&Z13,xa,3,FALSE)) -> #REF! | AH13: =IF(ISNA(VLOOKUP(AG13,tinh,2,FALSE)),"",VLOOKUP(AG13,tinh,2,FALSE)) | AJ13: =IF(ISNA(VLOOKUP(AI13&AH13,huyen,3,FALSE)),"",VLOOKUP(AI13&AH13,huyen,3,FALSE)) | AL13: =IF(ISNA(VLOOKUP(AK13&AJ13,xa,3,FALSE)),"",VLOOKUP(AK13&AJ13,xa,3,FALSE)) -> #REF!
G14: =IF(ISNA(VLOOKUP(F14,tinh,2,FALSE)),"",VLOOKUP(F14,tinh,2,FALSE)) | I14: =IF(ISNA(VLOOKUP(H14&G14,huyen,3,FALSE)),"",VLOOKUP(H14&G14,huyen,3,FALSE)) | K14: =IF(ISNA(VLOOKUP(J14&I14,xa,3,FALSE)),"",VLOOKUP(J14&I14,xa,3,FALSE)) -> #REF! | N14: =IF(ISNA(VLOOKUP(M14,ma_mqh,2,FALSE)),"",VLOOKUP(M14,ma_mqh,2,FALSE)) | X14: =IF(ISNA(VLOOKUP(W14,tinh,2,FALSE)),"",VLOOKUP(W14,tinh,2,FALSE)) | Z14: =IF(ISNA(VLOOKUP(Y14&X14,huyen,3,FALSE)),"",VLOOKUP(Y14&X14,huyen,3,FALSE)) | AB14: =IF(ISNA(VLOOKUP(AA14&Z14,xa,3,FALSE)),"",VLOOKUP(AA14&Z14,xa,3,FALSE)) -> #REF! | AH14: =IF(ISNA(VLOOKUP(AG14,tinh,2,FALSE)),"",VLOOKUP(AG14,tinh,2,FALSE)) | AJ14: =IF(ISNA(VLOOKUP(AI14&AH14,huyen,3,FALSE)),"",VLOOKUP(AI14&AH14,huyen,3,FALSE)) | AL14: =IF(ISNA(VLOOKUP(AK14&AJ14,xa,3,FALSE)),"",VLOOKUP(AK14&AJ14,xa,3,FALSE)) -> #REF!
G15: =IF(ISNA(VLOOKUP(F15,tinh,2,FALSE)),"",VLOOKUP(F15,tinh,2,FALSE)) | I15: =IF(ISNA(VLOOKUP(H15&G15,huyen,3,FALSE)),"",VLOOKUP(H15&G15,huyen,3,FALSE)) | K15: =IF(ISNA(VLOOKUP(J15&I15,xa,3,FALSE)),"",VLOOKUP(J15&I15,xa,3,FALSE)) -> #REF! | N15: =IF(ISNA(VLOOKUP(M15,ma_mqh,2,FALSE)),"",VLOOKUP(M15,ma_mqh,2,FALSE)) | X15: =IF(ISNA(VLOOKUP(W15,tinh,2,FALSE)),"",VLOOKUP(W15,tinh,2,FALSE)) | Z15: =IF(ISNA(VLOOKUP(Y15&X15,huyen,3,FALSE)),"",VLOOKUP(Y15&X15,huyen,3,FALSE)) | AB15: =IF(ISNA(VLOOKUP(AA15&Z15,xa,3,FALSE)),"",VLOOKUP(AA15&Z15,xa,3,FALSE)) -> #REF! | AH15: =IF(ISNA(VLOOKUP(AG15,tinh,2,FALSE)),"",VLOOKUP(AG15,tinh,2,FALSE)) | AJ15: =IF(ISNA(VLOOKUP(AI15&AH15,huyen,3,FALSE)),"",VLOOKUP(AI15&AH15,huyen,3,FALSE)) | AL15: =IF(ISNA(VLOOKUP(AK15&AJ15,xa,3,FALSE)),"",VLOOKUP(AK15&AJ15,xa,3,FALSE)) -> #REF!
G16: =IF(ISNA(VLOOKUP(F16,tinh,2,FALSE)),"",VLOOKUP(F16,tinh,2,FALSE)) | I16: =IF(ISNA(VLOOKUP(H16&G16,huyen,3,FALSE)),"",VLOOKUP(H16&G16,huyen,3,FALSE)) | K16: =IF(ISNA(VLOOKUP(J16&I16,xa,3,FALSE)),"",VLOOKUP(J16&I16,xa,3,FALSE)) -> #REF! | N16: =IF(ISNA(VLOOKUP(M16,ma_mqh,2,FALSE)),"",VLOOKUP(M16,ma_mqh,2,FALSE)) | X16: =IF(ISNA(VLOOKUP(W16,tinh,2,FALSE)),"",VLOOKUP(W16,tinh,2,FALSE)) | Z16: =IF(ISNA(VLOOKUP(Y16&X16,huyen,3,FALSE)),"",VLOOKUP(Y16&X16,huyen,3,FALSE)) | AB16: =IF(ISNA(VLOOKUP(AA16&Z16,xa,3,FALSE)),"",VLOOKUP(AA16&Z16,xa,3,FALSE)) -> #REF! | AH16: =IF(ISNA(VLOOKUP(AG16,tinh,2,FALSE)),"",VLOOKUP(AG16,tinh,2,FALSE)) | AJ16: =IF(ISNA(VLOOKUP(AI16&AH16,huyen,3,FALSE)),"",VLOOKUP(AI16&AH16,huyen,3,FALSE)) | AL16: =IF(ISNA(VLOOKUP(AK16&AJ16,xa,3,FALSE)),"",VLOOKUP(AK16&AJ16,xa,3,FALSE)) -> #REF!
... G99: =IF(ISNA(VLOOKUP(F99,tinh,2,FALSE)),"",VLOOKUP(F99,tinh,2,FALSE)) | I99: =IF(ISNA(VLOOKUP(H99&G99,huyen,3,FALSE)),"",VLOOKUP(H99&G99,huyen,3,FALSE)) | K99: =IF(ISNA(VLOOKUP(J99&I99,xa,3,FALSE)),"",VLOOKUP(J99&I99,xa,3,FALSE)) -> #REF! | N99: =IF(ISNA(VLOOKUP(M99,ma_mqh,2,FALSE)),"",VLOOKUP(M99,ma_mqh,2,FALSE)) | X99: =IF(ISNA(VLOOKUP(W99,tinh,2,FALSE)),"",VLOOKUP(W99,tinh,2,FALSE)) | Z99: =IF(ISNA(VLOOKUP(Y99&X99,huyen,3,FALSE)),"",VLOOKUP(Y99&X99,huyen,3,FALSE)) | AB99: =IF(ISNA(VLOOKUP(AA99&Z99,xa,3,FALSE)),"",VLOOKUP(AA99&Z99,xa,3,FALSE)) -> #REF! | AH99: =IF(ISNA(VLOOKUP(AG99,tinh,2,FALSE)),"",VLOOKUP(AG99,tinh,2,FALSE)) | AJ99: =IF(ISNA(VLOOKUP(AI99&AH99,huyen,3,FALSE)),"",VLOOKUP(AI99&AH99,huyen,3,FALSE)) | AL99: =IF(ISNA(VLOOKUP(AK99&AJ99,xa,3,FALSE)),"",VLOOKUP(AK99&AJ99,xa,3,FALSE)) -> #REF!
G100: =IF(ISNA(VLOOKUP(F100,tinh,2,FALSE)),"",VLOOKUP(F100,tinh,2,FALSE)) | I100: =IF(ISNA(VLOOKUP(H100&G100,huyen,3,FALSE)),"",VLOOKUP(H100&G100,huyen,3,FALSE)) | K100: =IF(ISNA(VLOOKUP(J100&I100,xa,3,FALSE)),"",VLOOKUP(J100&I100,xa,3,FALSE)) -> #REF! | X100: =IF(ISNA(VLOOKUP(W100,tinh,2,FALSE)),"",VLOOKUP(W100,tinh,2,FALSE)) | Z100: =IF(ISNA(VLOOKUP(Y100&X100,huyen,3,FALSE)),"",VLOOKUP(Y100&X100,huyen,3,FALSE)) | AB100: =IF(ISNA(VLOOKUP(AA100&Z100,xa,3,FALSE)),"",VLOOKUP(AA100&Z100,xa,3,FALSE)) -> #REF! | AH100: =IF(ISNA(VLOOKUP(AG100,tinh,2,FALSE)),"",VLOOKUP(AG100,tinh,2,FALSE)) | AJ100: =IF(ISNA(VLOOKUP(AI100&AH100,huyen,3,FALSE)),"",VLOOKUP(AI100&AH100,huyen,3,FALSE)) | AL100: =IF(ISNA(VLOOKUP(AK100&AJ100,xa,3,FALSE)),"",VLOOKUP(AK100&AJ100,xa,3,FALSE)) -> #REF!
G101: =IF(ISNA(VLOOKUP(F101,tinh,2,FALSE)),"",VLOOKUP(F101,tinh,2,FALSE)) | I101: =IF(ISNA(VLOOKUP(H101&G101,huyen,3,FALSE)),"",VLOOKUP(H101&G101,huyen,3,FALSE)) | K101: =IF(ISNA(VLOOKUP(J101&I101,xa,3,FALSE)),"",VLOOKUP(J101&I101,xa,3,FALSE)) -> #REF! | X101: =IF(ISNA(VLOOKUP(W101,tinh,2,FALSE)),"",VLOOKUP(W101,tinh,2,FALSE)) | Z101: =IF(ISNA(VLOOKUP(Y101&X101,huyen,3,FALSE)),"",VLOOKUP(Y101&X101,huyen,3,FALSE)) | AB101: =IF(ISNA(VLOOKUP(AA101&Z101,xa,3,FALSE)),"",VLOOKUP(AA101&Z101,xa,3,FALSE)) -> #REF! | AH101: =IF(ISNA(VLOOKUP(AG101,tinh,2,FALSE)),"",VLOOKUP(AG101,tinh,2,FALSE)) | AJ101: =IF(ISNA(VLOOKUP(AI101&AH101,huyen,3,FALSE)),"",VLOOKUP(AI101&AH101,huyen,3,FALSE)) | AL101: =IF(ISNA(VLOOKUP(AK101&AJ101,xa,3,FALSE)),"",VLOOKUP(AK101&AJ101,xa,3,FALSE)) -> #REF!
G102: =IF(ISNA(VLOOKUP(F102,tinh,2,FALSE)),"",VLOOKUP(F102,tinh,2,FALSE)) | I102: =IF(ISNA(VLOOKUP(H102&G102,huyen,3,FALSE)),"",VLOOKUP(H102&G102,huyen,3,FALSE)) | K102: =IF(ISNA(VLOOKUP(J102&I102,xa,3,FALSE)),"",VLOOKUP(J102&I102,xa,3,FALSE)) -> #REF! | X102: =IF(ISNA(VLOOKUP(W102,tinh,2,FALSE)),"",VLOOKUP(W102,tinh,2,FALSE)) | Z102: =IF(ISNA(VLOOKUP(Y102&X102,huyen,3,FALSE)),"",VLOOKUP(Y102&X102,huyen,3,FALSE)) | AB102: =IF(ISNA(VLOOKUP(AA102&Z102,xa,3,FALSE)),"",VLOOKUP(AA102&Z102,xa,3,FALSE)) -> #REF! | AH102: =IF(ISNA(VLOOKUP(AG102,tinh,2,FALSE)),"",VLOOKUP(AG102,tinh,2,FALSE)) | AJ102: =IF(ISNA(VLOOKUP(AI102&AH102,huyen,3,FALSE)),"",VLOOKUP(AI102&AH102,huyen,3,FALSE)) | AL102: =IF(ISNA(VLOOKUP(AK102&AJ102,xa,3,FALSE)),"",VLOOKUP(AK102&AJ102,xa,3,FALSE)) -> #REF!
G103: =IF(ISNA(VLOOKUP(F103,tinh,2,FALSE)),"",VLOOKUP(F103,tinh,2,FALSE)) | I103: =IF(ISNA(VLOOKUP(H103&G103,huyen,3,FALSE)),"",VLOOKUP(H103&G103,huyen,3,FALSE)) | K103: =IF(ISNA(VLOOKUP(J103&I103,xa,3,FALSE)),"",VLOOKUP(J103&I103,xa,3,FALSE)) -> #REF! | X103: =IF(ISNA(VLOOKUP(W103,tinh,2,FALSE)),"",VLOOKUP(W103,tinh,2,FALSE)) | Z103: =IF(ISNA(VLOOKUP(Y103&X103,huyen,3,FALSE)),"",VLOOKUP(Y103&X103,huyen,3,FALSE)) | AB103: =IF(ISNA(VLOOKUP(AA103&Z103,xa,3,FALSE)),"",VLOOKUP(AA103&Z103,xa,3,FALSE)) -> #REF! | AH103: =IF(ISNA(VLOOKUP(AG103,tinh,2,FALSE)),"",VLOOKUP(AG103,tinh,2,FALSE)) | AJ103: =IF(ISNA(VLOOKUP(AI103&AH103,huyen,3,FALSE)),"",VLOOKUP(AI103&AH103,huyen,3,FALSE)) | AL103: =IF(ISNA(VLOOKUP(AK103&AJ103,xa,3,FALSE)),"",VLOOKUP(AK103&AJ103,xa,3,FALSE)) -> #REF!
G104: =IF(ISNA(VLOOKUP(F104,tinh,2,FALSE)),"",VLOOKUP(F104,tinh,2,FALSE)) | I104: =IF(ISNA(VLOOKUP(H104&G104,huyen,3,FALSE)),"",VLOOKUP(H104&G104,huyen,3,FALSE)) | K104: =IF(ISNA(VLOOKUP(J104&I104,xa,3,FALSE)),"",VLOOKUP(J104&I104,xa,3,FALSE)) -> #REF! | X104: =IF(ISNA(VLOOKUP(W104,tinh,2,FALSE)),"",VLOOKUP(W104,tinh,2,FALSE)) | Z104: =IF(ISNA(VLOOKUP(Y104&X104,huyen,3,FALSE)),"",VLOOKUP(Y104&X104,huyen,3,FALSE)) | AB104: =IF(ISNA(VLOOKUP(AA104&Z104,xa,3,FALSE)),"",VLOOKUP(AA104&Z104,xa,3,FALSE)) -> #REF! | AH104: =IF(ISNA(VLOOKUP(AG104,tinh,2,FALSE)),"",VLOOKUP(AG104,tinh,2,FALSE)) | AJ104: =IF(ISNA(VLOOKUP(AI104&AH104,huyen,3,FALSE)),"",VLOOKUP(AI104&AH104,huyen,3,FALSE)) | AL104: =IF(ISNA(VLOOKUP(AK104&AJ104,xa,3,FALSE)),"",VLOOKUP(AK104&AJ104,xa,3,FALSE)) -> #REF!
G105: =IF(ISNA(VLOOKUP(F105,tinh,2,FALSE)),"",VLOOKUP(F105,tinh,2,FALSE)) | I105: =IF(ISNA(VLOOKUP(H105&G105,huyen,3,FALSE)),"",VLOOKUP(H105&G105,huyen,3,FALSE)) | K105: =IF(ISNA(VLOOKUP(J105&I105,xa,3,FALSE)),"",VLOOKUP(J105&I105,xa,3,FALSE)) -> #REF! | X105: =IF(ISNA(VLOOKUP(W105,tinh,2,FALSE)),"",VLOOKUP(W105,tinh,2,FALSE)) | Z105: =IF(ISNA(VLOOKUP(Y105&X105,huyen,3,FALSE)),"",VLOOKUP(Y105&X105,huyen,3,FALSE)) | AB105: =IF(ISNA(VLOOKUP(AA105&Z105,xa,3,FALSE)),"",VLOOKUP(AA105&Z105,xa,3,FALSE)) -> #REF! | AH105: =IF(ISNA(VLOOKUP(AG105,tinh,2,FALSE)),"",VLOOKUP(AG105,tinh,2,FALSE)) | AJ105: =IF(ISNA(VLOOKUP(AI105&AH105,huyen,3,FALSE)),"",VLOOKUP(AI105&AH105,huyen,3,FALSE)) | AL105: =IF(ISNA(VLOOKUP(AK105&AJ105,xa,3,FALSE)),"",VLOOKUP(AK105&AJ105,xa,3,FALSE)) -> #REF!
G106: =IF(ISNA(VLOOKUP(F106,tinh,2,FALSE)),"",VLOOKUP(F106,tinh,2,FALSE)) | I106: =IF(ISNA(VLOOKUP(H106&G106,huyen,3,FALSE)),"",VLOOKUP(H106&G106,huyen,3,FALSE)) | K106: =IF(ISNA(VLOOKUP(J106&I106,xa,3,FALSE)),"",VLOOKUP(J106&I106,xa,3,FALSE)) -> #REF! | X106: =IF(ISNA(VLOOKUP(W106,tinh,2,FALSE)),"",VLOOKUP(W106,tinh,2,FALSE)) | Z106: =IF(ISNA(VLOOKUP(Y106&X106,huyen,3,FALSE)),"",VLOOKUP(Y106&X106,huyen,3,FALSE)) | AB106: =IF(ISNA(VLOOKUP(AA106&Z106,xa,3,FALSE)),"",VLOOKUP(AA106&Z106,xa,3,FALSE)) -> #REF! | AH106: =IF(ISNA(VLOOKUP(AG106,tinh,2,FALSE)),"",VLOOKUP(AG106,tinh,2,FALSE)) | AJ106: =IF(ISNA(VLOOKUP(AI106&AH106,huyen,3,FALSE)),"",VLOOKUP(AI106&AH106,huyen,3,FALSE)) | AL106: =IF(ISNA(VLOOKUP(AK106&AJ106,xa,3,FALSE)),"",VLOOKUP(AK106&AJ106,xa,3,FALSE)) -> #REF!
G107: =IF(ISNA(VLOOKUP(F107,tinh,2,FALSE)),"",VLOOKUP(F107,tinh,2,FALSE)) | I107: =IF(ISNA(VLOOKUP(H107&G107,huyen,3,FALSE)),"",VLOOKUP(H107&G107,huyen,3,FALSE)) | K107: =IF(ISNA(VLOOKUP(J107&I107,xa,3,FALSE)),"",VLOOKUP(J107&I107,xa,3,FALSE)) -> #REF! | X107: =IF(ISNA(VLOOKUP(W107,tinh,2,FALSE)),"",VLOOKUP(W107,tinh,2,FALSE)) | Z107: =IF(ISNA(VLOOKUP(Y107&X107,huyen,3,FALSE)),"",VLOOKUP(Y107&X107,huyen,3,FALSE)) | AB107: =IF(ISNA(VLOOKUP(AA107&Z107,xa,3,FALSE)),"",VLOOKUP(AA107&Z107,xa,3,FALSE)) -> #REF! | AH107: =IF(ISNA(VLOOKUP(AG107,tinh,2,FALSE)),"",VLOOKUP(AG107,tinh,2,FALSE)) | AJ107: =IF(ISNA(VLOOKUP(AI107&AH107,huyen,3,FALSE)),"",VLOOKUP(AI107&AH107,huyen,3,FALSE)) | AL107: =IF(ISNA(VLOOKUP(AK107&AJ107,xa,3,FALSE)),"",VLOOKUP(AK107&AJ107,xa,3,FALSE)) -> #REF!
G108: =IF(ISNA(VLOOKUP(F108,tinh,2,FALSE)),"",VLOOKUP(F108,tinh,2,FALSE)) | I108: =IF(ISNA(VLOOKUP(H108&G108,huyen,3,FALSE)),"",VLOOKUP(H108&G108,huyen,3,FALSE)) | K108: =IF(ISNA(VLOOKUP(J108&I108,xa,3,FALSE)),"",VLOOKUP(J108&I108,xa,3,FALSE)) -> #REF! | X108: =IF(ISNA(VLOOKUP(W108,tinh,2,FALSE)),"",VLOOKUP(W108,tinh,2,FALSE)) | Z108: =IF(ISNA(VLOOKUP(Y108&X108,huyen,3,FALSE)),"",VLOOKUP(Y108&X108,huyen,3,FALSE)) | AB108: =IF(ISNA(VLOOKUP(AA108&Z108,xa,3,FALSE)),"",VLOOKUP(AA108&Z108,xa,3,FALSE)) -> #REF! | AH108: =IF(ISNA(VLOOKUP(AG108,tinh,2,FALSE)),"",VLOOKUP(AG108,tinh,2,FALSE)) | AJ108: =IF(ISNA(VLOOKUP(AI108&AH108,huyen,3,FALSE)),"",VLOOKUP(AI108&AH108,huyen,3,FALSE)) | AL108: =IF(ISNA(VLOOKUP(AK108&AJ108,xa,3,FALSE)),"",VLOOKUP(AK108&AJ108,xa,3,FALSE)) -> #REF!
G109: =IF(ISNA(VLOOKUP(F109,tinh,2,FALSE)),"",VLOOKUP(F109,tinh,2,FALSE)) | I109: =IF(ISNA(VLOOKUP(H109&G109,huyen,3,FALSE)),"",VLOOKUP(H109&G109,huyen,3,FALSE)) | K109: =IF(ISNA(VLOOKUP(J109&I109,xa,3,FALSE)),"",VLOOKUP(J109&I109,xa,3,FALSE)) -> #REF! | X109: =IF(ISNA(VLOOKUP(W109,tinh,2,FALSE)),"",VLOOKUP(W109,tinh,2,FALSE)) | Z109: =IF(ISNA(VLOOKUP(Y109&X109,huyen,3,FALSE)),"",VLOOKUP(Y109&X109,huyen,3,FALSE)) | AB109: =IF(ISNA(VLOOKUP(AA109&Z109,xa,3,FALSE)),"",VLOOKUP(AA109&Z109,xa,3,FALSE)) -> #REF! | AH109: =IF(ISNA(VLOOKUP(AG109,tinh,2,FALSE)),"",VLOOKUP(AG109,tinh,2,FALSE)) | AJ109: =IF(ISNA(VLOOKUP(AI109&AH109,huyen,3,FALSE)),"",VLOOKUP(AI109&AH109,huyen,3,FALSE)) | AL109: =IF(ISNA(VLOOKUP(AK109&AJ109,xa,3,FALSE)),"",VLOOKUP(AK109&AJ109,xa,3,FALSE)) -> #REF!
G110: =IF(ISNA(VLOOKUP(F110,tinh,2,FALSE)),"",VLOOKUP(F110,tinh,2,FALSE)) | I110: =IF(ISNA(VLOOKUP(H110&G110,huyen,3,FALSE)),"",VLOOKUP(H110&G110,huyen,3,FALSE)) | K110: =IF(ISNA(VLOOKUP(J110&I110,xa,3,FALSE)),"",VLOOKUP(J110&I110,xa,3,FALSE)) -> #REF! | X110: =IF(ISNA(VLOOKUP(W110,tinh,2,FALSE)),"",VLOOKUP(W110,tinh,2,FALSE)) | Z110: =IF(ISNA(VLOOKUP(Y110&X110,huyen,3,FALSE)),"",VLOOKUP(Y110&X110,huyen,3,FALSE)) | AB110: =IF(ISNA(VLOOKUP(AA110&Z110,xa,3,FALSE)),"",VLOOKUP(AA110&Z110,xa,3,FALSE)) -> #REF! | AH110: =IF(ISNA(VLOOKUP(AG110,tinh,2,FALSE)),"",VLOOKUP(AG110,tinh,2,FALSE)) | AJ110: =IF(ISNA(VLOOKUP(AI110&AH110,huyen,3,FALSE)),"",VLOOKUP(AI110&AH110,huyen,3,FALSE)) | AL110: =IF(ISNA(VLOOKUP(AK110&AJ110,xa,3,FALSE)),"",VLOOKUP(AK110&AJ110,xa,3,FALSE)) -> #REF!
G111: =IF(ISNA(VLOOKUP(F111,tinh,2,FALSE)),"",VLOOKUP(F111,tinh,2,FALSE)) | I111: =IF(ISNA(VLOOKUP(H111&G111,huyen,3,FALSE)),"",VLOOKUP(H111&G111,huyen,3,FALSE)) | K111: =IF(ISNA(VLOOKUP(J111&I111,xa,3,FALSE)),"",VLOOKUP(J111&I111,xa,3,FALSE)) -> #REF! | X111: =IF(ISNA(VLOOKUP(W111,tinh,2,FALSE)),"",VLOOKUP(W111,tinh,2,FALSE)) | Z111: =IF(ISNA(VLOOKUP(Y111&X111,huyen,3,FALSE)),"",VLOOKUP(Y111&X111,huyen,3,FALSE)) | AB111: =IF(ISNA(VLOOKUP(AA111&Z111,xa,3,FALSE)),"",VLOOKUP(AA111&Z111,xa,3,FALSE)) -> #REF! | AH111: =IF(ISNA(VLOOKUP(AG111,tinh,2,FALSE)),"",VLOOKUP(AG111,tinh,2,FALSE)) | AJ111: =IF(ISNA(VLOOKUP(AI111&AH111,huyen,3,FALSE)),"",VLOOKUP(AI111&AH111,huyen,3,FALSE)) | AL111: =IF(ISNA(VLOOKUP(AK111&AJ111,xa,3,FALSE)),"",VLOOKUP(AK111&AJ111,xa,3,FALSE)) -> #REF!
... G350: =IF(ISNA(VLOOKUP(F350,tinh,2,FALSE)),"",VLOOKUP(F350,tinh,2,FALSE)) | I350: =IF(ISNA(VLOOKUP(H350&G350,huyen,3,FALSE)),"",VLOOKUP(H350&G350,huyen,3,FALSE)) | K350: =IF(ISNA(VLOOKUP(J350&I350,xa,3,FALSE)),"",VLOOKUP(J350&I350,xa,3,FALSE)) -> #REF! | X350: =IF(ISNA(VLOOKUP(W350,tinh,2,FALSE)),"",VLOOKUP(W350,tinh,2,FALSE)) | Z350: =IF(ISNA(VLOOKUP(Y350&X350,huyen,3,FALSE)),"",VLOOKUP(Y350&X350,huyen,3,FALSE)) | AB350: =IF(ISNA(VLOOKUP(AA350&Z350,xa,3,FALSE)),"",VLOOKUP(AA350&Z350,xa,3,FALSE)) -> #REF! | AH350: =IF(ISNA(VLOOKUP(AG350,tinh,2,FALSE)),"",VLOOKUP(AG350,tinh,2,FALSE)) | AJ350: =IF(ISNA(VLOOKUP(AI350&AH350,huyen,3,FALSE)),"",VLOOKUP(AI350&AH350,huyen,3,FALSE)) | AL350: =IF(ISNA(VLOOKUP(AK350&AJ350,xa,3,FALSE)),"",VLOOKUP(AK350&AJ350,xa,3,FALSE)) -> #REF!

Sheet Bảng kê
A1: ID Lao Động (ID Lao động ở Sheet Dữ Liệu) | B1: Họ tên ( 1 ) | C1: Mã số BHXH ( 2 ) | D1: Tên văn bản ( 3 ) | E1: Số văn bản ( 4 ) | F1: Ngày ban hành ( 5 ) | G1: Ngày hiệu lực ( 6 ) | H1: Cơ quan ban hành ( 7 ) | I1: Trích yếu văn bản ( 8) | J1: Trích lược nội dung thẩm định ( 9 )
A3: STT | B3: HoTen | C3: MasoBHXH | D3: TenLoaiVanBan | E3: SoVanBan | F3: NgayBanHanh | G3: NgayHieuLuc | H3: CoQuanBanHanh | I3: TrichYeu | J3: NoiDungThamDinh
A4: 1 | B4: Bùi Văn A | C4: 1234567890 | D4: Hợp đồng lao động | E4: 8765 | F4: 02/02/2000 | G4: 02/02/2001 | H4: Công ty

Sheet Dân tộc
A1: DANH MỤC DÂN TỘC
A2: Tên dân tộc | B2: Mã dân tộc | C2: Tên khác
A3: Kinh | B3: 01 | C3: Việt
A4: Tày | B4: 02 | C4: Thổ, Ngạn, Phén, Thù lao, Pa Dí
A5: Thái | B5: 03 | C5: Tày, Tày khao (Thái trắng), Tày Dăm (Thái Đen), Tày Mười Tây Thanh, Màn Thanh (Hang Ông (Tày Mường), Pi Thay, Thổ Đà Bắc
A6: Hoa | B6: 04 | C6: Hán, Triều Châu, Phúc Kiến, Quảng Đông, Hải Nam, Hạ, Xạ Phạng
A7: Khơ-me | B7: 05 | C7: Cur, Cul, Cu, Thổ, Việt gốc Miên, Khơ-me, Krôm
A8: Mường | B8: 06 | C8: Mol, Mual, Mọi, Mọi Bi, Ao Tá, (Ậu Tá)
A9: Nùng | B9: 07 | C9: Xuồng, Giang, Nùng An, Phàn Sinh, Nùng Cháo, Nùng Lòi, Quý Rim, Khèn Lài, ...
A10: Hmông | B10: 08 | C10: Mèo, Mẹo, Hoa, Mèo Xanh, Mèo Đỏ, Mèo Đen, Ná Mẻo, Mán Trắng
A11: Dao | B11: 09 | C11: Mán, Động, Trại, Xá, Dìu Miền, Kiềm, Miền, Quần Trắng, Dao Đỏ, Quần Chẹt, Lô Gang, Dao Tiền, Thanh Y, Lan Tẻn, Đại Bản,Tiểu Bản, Cóc Ngáng, Cóc Mùn, Sơn Đầu, ...
A12: Gia-rai | B12: 10 | C12: Giơ-rai, Tơ-buăn, Chơ-rai, Hơ-bau, Hđrung, Chor, ...
A13: Ngái | B13: 11 | C13: Xín, Lê, Đản, Khách Gia
A14: Ê-đê | B14: 12 | C14: Ra-đê, Đê, Kpạ, A-đham, Krung, Ktul, Đliê Ruê, Blô, E-pan, Mđhur, Bih, ...
A15: Ba-na | B15: 13 | C15: Gơ-lar, Tơ-lô, Giơ-lâng (Y-Lăng), Rơ-ngao, Krem, Roh, ConKđe, A-la Công, Kpăng Công, Bơ-nâm
A16: Xơ-đăng | B16: 14 | C16: Xơ-teng, Hđang, Tơ-đra, Mơ-nâm, Ha-lăng, Ca-dông, Kmrâng, Con Lan, Bri-la, Tang
A17: Sán Chay | B17: 15 | C17: Cao Lan-Sán chỉ, Cao Lan, Mán Cao Lan, Hờn Bạn, Sán Chỉ (Sơn Tử)
A18: Cơ-ho | B18: 16 | C18: Xrê, Nốp (Tu Lốp), Cơ-don, Chil, Lat (Lach), Trinh
A19: Chăm | B19: 17 | C19: Chàm, Chiêm Thành, Hroi
A20: Sán Dìu | B20: 18 | C20: Sán Dẻo, Trại, Trại Đất, Mán Quần Cộc
A21: Hrê | B21: 19 | C21: Chăm Rê, Chom, Krẹ Lũy
A22: Mnông | B22: 20 | C22: Pnông, Nông, Pré, Bu-đâng, ĐiPri, Biat, Gar, Rơ-lam, Chil
A23: Ra-glai | B23: 21 | C23: Ra-clây, Rai, Noang, La-oang
... A44: Lự | B44: 42 | C44: Lừ, Nhuồn Duôn, Mun Di
A45: Lô Lô | B45: 43
A46: Chứt | B46: 44 | C46: Sách, May, Rục, Mã-liêng, A-rem, Tu vang, Pa-leng, Xơ-lang, Tơ-hung, Chà-củi, Tắc-củi, U-mo, Xá Lá Vàng
A47: Mảng | B47: 45 | C47: Mảng Ư, Xá Lá Vàng
A48: Pà Thẻn | B48: 46 | C48: Pà Hưng, Tống
A49: Cơ Lao | B49: 47
A50: Cống | B50: 48 | C50: Xắm Khống, Mấng Nhé, Xá Xeng
A51: Bố Y | B51: 49 | C51: Chủng Chá, Trọng Gia, Tu Dí, Tu Dìn
A52: Si La | B52: 50 | C52: Cù Dề Xừ, Khả pẻ
A53: Pu Péo | B53: 51 | C53: Ka Bèo, Pen Ti Lô Lô
A54: Brâu | B54: 52 | C54: Brao
A55: Ơ Đu | B55: 53 | C55: Tày Hạt
A56: Rơ-măm | B56: 54
A57: Ca dong | B57: 55
A58: Người nước ngoài | B58: 99

Sheet QuocTich
A1: DANH MỤC QUỐC TỊCH
A2: Tên Quốc gia/ Vùng lãnh thổ | B2: Mã
A3: Việt Nam | B3: VN
A4: AFGHANISTAN | B4: AF
A5: ÅLAND ISLANDS | B5: AX
A6: ALBANIA | B6: AL
A7: ALGERIA | B7: DZ
A8: AMERICAN SAMOA | B8: AS
A9: ANDORRA | B9: AD
A10: ANGOLA | B10: AO
A11: ANGUILLA | B11: AI
A12: ANTARCTICA | B12: AQ
A13: ANTIGUA AND BARBUDA | B13: AG
... A243: ZIMBABWE | B243: ZW

Sheet BenhVien
B1: DANH MỤC BỆNH VIỆN
B2: Tên bệnh viện | C2: Mã bệnh viện | D2: Mã tỉnh
A3: =B3&D3 -> Bệnh viện đa khoa Phương Đông01 | B3: Bệnh viện đa khoa Phương Đông | C3: 01258 | D3: 01
A4: =B4&D4 -> Bệnh viện Hữu Nghị01 | B4: Bệnh viện Hữu Nghị | C4: 01001 | D4: 01
A5: =B5&D5 -> Phòng khám A thuộc BVĐK Xanh Pôn01 | B5: Phòng khám A thuộc BVĐK Xanh Pôn | C5: 01002 | D5: 01
A6: =B6&D6 -> Bệnh viện đa khoa Xanh Pôn01 | B6: Bệnh viện đa khoa Xanh Pôn | C6: 01003 | D6: 01
A7: =B7&D7 -> Bệnh viện đa khoa Đống Đa01 | B7: Bệnh viện đa khoa Đống Đa | C7: 01004 | D7: 01
A8: =B8&D8 -> Bệnh viện Hữu Nghị Việt Nam - Cu Ba01 | B8: Bệnh viện Hữu Nghị Việt Nam - Cu Ba | C8: 01005 | D8: 01
A9: =B9&D9 -> Bệnh viện Thanh Nhàn01 | B9: Bệnh viện Thanh Nhàn | C9: 01006 | D9: 01
A10: =B10&D10 -> Bệnh viện E01 | B10: Bệnh viện E | C10: 01007 | D10: 01
A11: =B11&D11 -> Bệnh viện Bưu điện (Bộ Bưu Chính v.thông)01 | B11: Bệnh viện Bưu điện (Bộ Bưu Chính v.thông) | C11: 01009 | D11: 01
A12: =B12&D12 -> Công ty cổ phần Bệnh viện Giao thông vận tải01 | B12: Công ty cổ phần Bệnh viện Giao thông vận tải | C12: 01010 | D12: 01
A13: =B13&D13 -> Phòng khám đa khoa Đông Mỹ (TYT xã Nam Phù)01 | B13: Phòng khám đa khoa Đông Mỹ (TYT xã Nam Phù) | C13: 01012 | D13: 01
A14: =B14&D14 -> Bệnh viện Đa khoa Nông nghiệp01 | B14: Bệnh viện Đa khoa Nông nghiệp | C14: 01013 | D14: 01
... A11869: =B11869&D11869 -> PHÒNG KHÁM ĐA KHOA THANH VŨ MEDIC ĐẦM DƠI96 | B11869: PHÒNG KHÁM ĐA KHOA THANH VŨ MEDIC ĐẦM DƠI | C11869: 96180 | D11869: 96
A11870: =B11870&D11870
A11871: =B11871&D11871
A11872: =B11872&D11872
A11873: =B11873&D11873
A11874: =B11874&D11874
A11875: =B11875&D11875
A11876: =B11876&D11876
A11877: =B11877&D11877
A11878: =B11878&D11878
A11879: =B11879&D11879
A11880: =B11880&D11880
A11881: =B11881&D11881
... A12824: =B12824&D12824

Sheet Tinh
A1: DANH MỤC TỈNH THÀNH PHỐ
A2: TÊN TỈNH | B2: MÃ TỈNH
A3: Thành phố Hà Nội | B3: 01
A4: Tỉnh Cao Bằng | B4: 04
A5: Tỉnh Tuyên Quang | B5: 08
A6: Tỉnh Điện Biên | B6: 11
A7: Tỉnh Lai Châu | B7: 12
A8: Tỉnh Sơn La | B8: 14
A9: Tỉnh Lào Cai | B9: 15
A10: Tỉnh Thái Nguyên | B10: 19
A11: Tỉnh Lạng Sơn | B11: 20
A12: Tỉnh Quảng Ninh | B12: 22
A13: Tỉnh Bắc Ninh | B13: 24
A14: Tỉnh Phú Thọ | B14: 25
A15: Thành phố Hải Phòng | B15: 31
A16: Tỉnh Hưng Yên | B16: 33
A17: Tỉnh Ninh Bình | B17: 37
... A36: Tỉnh Cà Mau | B36: 96

Sheet TinhBenhVien
A1: DANH MỤC TỈNH THÀNH PHỐ
A2: TÊN TỈNH | B2: MÃ TỈNH
A3: Thành phố Hà Nội | B3: 01
A4: Tỉnh Cao Bằng | B4: 04
A5: Tỉnh Tuyên Quang | B5: 08
A6: Tỉnh Điện Biên | B6: 11
A7: Tỉnh Lai Châu | B7: 12
A8: Tỉnh Sơn La | B8: 14
A9: Tỉnh Lào Cai | B9: 15
A10: Tỉnh Thái Nguyên | B10: 19
A11: Tỉnh Lạng Sơn | B11: 20
A12: Tỉnh Quảng Ninh | B12: 22
A13: Tỉnh Bắc Ninh | B13: 24
... A37: Bộ quốc phòng | B37: 97

Sheet Xa
B1: DANH MỤC QUẬN HUYỆN
B2: Tên huyện | C2: Mã huyện | D2: Mã tỉnh
A3: =B3&D3 -> Phường Hoàn Kiếm01 | B3: Phường Hoàn Kiếm | C3: 00070 | D3: 01
A4: =B4&D4 -> Phường Cửa Nam01 | B4: Phường Cửa Nam | C4: 00082 | D4: 01
A5: =B5&D5 -> Phường Ba Đình01 | B5: Phường Ba Đình | C5: 00004 | D5: 01
A6: =B6&D6 -> Phường Ngọc Hà01 | B6: Phường Ngọc Hà | C6: 00008 | D6: 01
A7: =B7&D7 -> Phường Giảng Võ01 | B7: Phường Giảng Võ | C7: 00025 | D7: 01
A8: =B8&D8 -> Phường Hai Bà Trưng01 | B8: Phường Hai Bà Trưng | C8: 00256 | D8: 01
A9: =B9&D9 -> Phường Vĩnh Tuy01 | B9: Phường Vĩnh Tuy | C9: 00283 | D9: 01
A10: =B10&D10 -> Phường Bạch Mai01 | B10: Phường Bạch Mai | C10: 00292 | D10: 01
A11: =B11&D11 -> Phường Đống Đa01 | B11: Phường Đống Đa | C11: 00235 | D11: 01
A12: =B12&D12 -> Phường Kim Liên01 | B12: Phường Kim Liên | C12: 00229 | D12: 01
A13: =B13&D13 -> Phường Văn Miếu - Quốc Tử Giám01 | B13: Phường Văn Miếu - Quốc Tử Giám | C13: 00226 | D13: 01
A14: =B14&D14 -> Phường Láng01 | B14: Phường Láng | C14: 00199 | D14: 01
... A308: =B308&D308 -> Xã Khuôn Lùng08 | B308: Xã Khuôn Lùng | C308: 01147 | D308: 08
A309: =B309&D309 -> Xã Mường Phăng11 | B309: Xã Mường Phăng | C309: 03325 | D309: 11
A310: =B310&D310 -> Phường Điện Biên Phủ11 | B310: Phường Điện Biên Phủ | C310: 03127 | D310: 11
A311: =B311&D311 -> Phường Mường Thanh11 | B311: Phường Mường Thanh | C311: 03334 | D311: 11
A312: =B312&D312 -> Phường Mường Lay11 | B312: Phường Mường Lay | C312: 03151 | D312: 11
A313: =B313&D313 -> Xã Thanh Nưa11 | B313: Xã Thanh Nưa | C313: 03328 | D313: 11
A314: =B314&D314 -> Xã Thanh An11 | B314: Xã Thanh An | C314: 03352 | D314: 11
A315: =B315&D315 -> Xã Thanh Yên11 | B315: Xã Thanh Yên | C315: 03349 | D315: 11
A316: =B316&D316 -> Xã Sam Mứn11 | B316: Xã Sam Mứn | C316: 03356 | D316: 11
A317: =B317&D317 -> Xã Núa Ngam11 | B317: Xã Núa Ngam | C317: 03358 | D317: 11
A318: =B318&D318 -> Xã Mường Nhà11 | B318: Xã Mường Nhà | C318: 03368 | D318: 11
A319: =B319&D319 -> Xã Tuần Giáo11 | B319: Xã Tuần Giáo | C319: 03253 | D319: 11
A320: =B320&D320 -> Xã Quài Tở11 | B320: Xã Quài Tở | C320: 03295 | D320: 11
... A1137: =B1137&D1137 -> Xã Kim Thành31 | B1137: Xã Kim Thành | C1137: 10804 | D1137: 31
A1138: =B1138&D1138 -> Phường Phố Hiến33 | B1138: Phường Phố Hiến | C1138: 11953 | D1138: 33
A1139: =B1139&D1139 -> Phường Sơn Nam33 | B1139: Phường Sơn Nam | C1139: 11983 | D1139: 33
A1140: =B1140&D1140 -> Phường Hồng Châu33 | B1140: Phường Hồng Châu | C1140: 11980 | D1140: 33
A1141: =B1141&D1141 -> Phường Mỹ Hào33 | B1141: Phường Mỹ Hào | C1141: 12103 | D1141: 33
A1142: =B1142&D1142 -> Phường Đường Hào33 | B1142: Phường Đường Hào | C1142: 12133 | D1142: 33
A1143: =B1143&D1143 -> Phường Thượng Hồng33 | B1143: Phường Thượng Hồng | C1143: 12127 | D1143: 33
A1144: =B1144&D1144 -> Xã Tân Hưng33 | B1144: Xã Tân Hưng | C1144: 11977 | D1144: 33
A1145: =B1145&D1145 -> Xã Hoàng Hoa Thám33 | B1145: Xã Hoàng Hoa Thám | C1145: 12337 | D1145: 33
A1146: =B1146&D1146 -> Xã Tiên Lữ33 | B1146: Xã Tiên Lữ | C1146: 12364 | D1146: 33
A1147: =B1147&D1147 -> Xã Tiên Hoa33 | B1147: Xã Tiên Hoa | C1147: 12361 | D1147: 33
A1148: =B1148&D1148 -> Xã Quang Hưng33 | B1148: Xã Quang Hưng | C1148: 12391 | D1148: 33
A1149: =B1149&D1149 -> Xã Đoàn Đào33 | B1149: Xã Đoàn Đào | C1149: 12406 | D1149: 33
...

Sheet Mức hưởng BHYT
A1: Mã | B1: Diễn giải
